Workbook

Sheet Récap
A1: LES SOLDES
A2: SOLDE DES IMPAYÉ BLOQUÉ | B2: =SUMIFS('Liste de la paie'!H4:H3291,'Liste de la paie'!L4:L3291,"Impayé",'Liste de la paie'!M4:M3291,"BLOQUÉ") -> 0
A3: SOLDE DES IMPAYÉ EN COURS | B3: =SUMIFS('Liste de la paie'!H4:H3291,'Liste de la paie'!L4:L3291,"Impayé",'Liste de la paie'!M4:M3291,"") -> 69720.764
A4: SOLDE PHYSIQUE | B4: =SUM(C7:E31)-SUM(F7:F31) -> -23344.538
A6: Quinzaine | B6: POINTAGE ESPECES | C6: Montant alimentation VIREMENT BGF | D6: Montant alimentation MR OMAR | E6: ALIM PAR CAISSE RECETTES | F6: Montant payé | G6: Montant Impayé | H6: Solde
A7: 31/06/2025 | B7: 67698.83 | C7: 0 | F7: =SUMIFS('Liste de la paie'!H4:H9659,'Liste de la paie'!A4:A9659,"30/06/2025",'Liste de la paie'!L4:L9659,"Payé") -> 5290.4344 | G7: =SUMIFS('Liste de la paie'!$H$4:$H$9659,'Liste de la paie'!$A$4:$A$9659,"30/06/2025",'Liste de la paie'!$L$4:$L$9659,"Impayé") -> 62408.398 | H7: =SUM(C7:E7)-F7 -> -5290.4344
A8: 1Q07/2025 | B8: =SUMIFS('Liste de la paie'!$H$4:$H$14215,'Liste de la paie'!$F$4:$F$14215,A8) -> 147201 | C8: 150000 | F8: =SUMIFS('Liste de la paie'!H4:H9660,'Liste de la paie'!A4:A9660,"1Q07/2025",'Liste de la paie'!L4:L9660,"Payé") -> 146551 | G8: =SUMIFS('Liste de la paie'!$H$4:$H$9659,'Liste de la paie'!$A$4:$A$9659,"1Q07/2025",'Liste de la paie'!$L$4:$L$9659,"Impayé") -> 650 | H8: =SUM(C8:E8)-F8 -> 3449
A9: 2Q07/2025 | B9: =SUMIFS('Liste de la paie'!$H$4:$H$14215,'Liste de la paie'!$F$4:$F$14215,A9) -> 102934.5 | C9: 103000 | F9: =SUMIFS('Liste de la paie'!$H$4:$H14216,'Liste de la paie'!$A$4:$A14216,A9,'Liste de la paie'!$L$4:$L14216,"Payé") -> 102761.5 | G9: =SUMIFS('Liste de la paie'!$H$4:$H14216,'Liste de la paie'!$A$4:$A14216,A9,'Liste de la paie'!$L$4:$L14216,"Impayé") -> 173 | H9: =SUM(C9:E9)-F9 -> 238.5
A10: 1Q08/2025 | B10: =SUMIFS('Liste de la paie'!$H$4:$H$14215,'Liste de la paie'!$F$4:$F$14215,A10) -> 170336 | C10: 171000 | F10: =SUMIFS('Liste de la paie'!$H$4:$H14217,'Liste de la paie'!$A$4:$A14217,A10,'Liste de la paie'!$L$4:$L14217,"Payé") -> 169121 | G10: =SUMIFS('Liste de la paie'!$H$4:$H14217,'Liste de la paie'!$A$4:$A14217,A10,'Liste de la paie'!$L$4:$L14217,"Impayé") -> 1215 | H10: =SUM(C10:E10)-F10 -> 1879
A11: 2Q08/2025 | B11: =SUMIFS('Liste de la paie'!$H$4:$H$14215,'Liste de la paie'!$F$4:$F$14215,A11) -> 88837 | C11: 90000 | F11: =SUMIFS('Liste de la paie'!$H$4:$H14218,'Liste de la paie'!$A$4:$A14218,A11,'Liste de la paie'!$L$4:$L14218,"Payé") -> 87970 | G11: =SUMIFS('Liste de la paie'!$H$4:$H14218,'Liste de la paie'!$A$4:$A14218,A11,'Liste de la paie'!$L$4:$L14218,"Impayé") -> 867 | H11: =SUM(C11:E11)-F11 -> 2030
A12: 1Q09/2025 | B12: =SUMIFS('Liste de la paie'!$H$4:$H$14215,'Liste de la paie'!$F$4:$F$14215,A12) -> 106702.5 | C12: 110000 | F12: =SUMIFS('Liste de la paie'!$H$4:$H14219,'Liste de la paie'!$A$4:$A14219,A12,'Liste de la paie'!$L$4:$L14219,"Payé") -> 106095.5 | G12: =SUMIFS('Liste de la paie'!$H$4:$H14219,'Liste de la paie'!$A$4:$A14219,A12,'Liste de la paie'!$L$4:$L14219,"Impayé") -> 607 | H12: =SUM(C12:E12)-F12 -> 3904.5
A13: 2Q09/2025 | B13: =SUMIFS('Liste de la paie'!$H$4:$H$14215,'Liste de la paie'!$F$4:$F$14215,A13) -> 159613 | C13: 160000 | F13: =SUMIFS('Liste de la paie'!$H$4:$H14220,'Liste de la paie'!$A$4:$A14220,A13,'Liste de la paie'!$L$4:$L14220,"Payé") -> 159091 | G13: =SUMIFS('Liste de la paie'!$H$4:$H14220,'Liste de la paie'!$A$4:$A14220,A13,'Liste de la paie'!$L$4:$L14220,"Impayé") -> 522 | H13: =SUM(C13:E13)-F13 -> 909
A14: 1Q10/2025 | B14: =SUMIFS('Liste de la paie'!$H$4:$H$14215,'Liste de la paie'!$F$4:$F$14215,A14) -> 136737 | C14: 140000 | F14: =SUMIFS('Liste de la paie'!$H$4:$H14221,'Liste de la paie'!$A$4:$A14221,A14,'Liste de la paie'!$L$4:$L14221,"Payé") -> 136647 | G14: =SUMIFS('Liste de la paie'!$H$4:$H14221,'Liste de la paie'!$A$4:$A14221,A14,'Liste de la paie'!$L$4:$L14221,"Impayé") -> 90 | H14: =SUM(C14:E14)-F14 -> 3353
A15: 2Q10/2025 | B15: =SUMIFS('Liste de la paie'!$H$4:$H$14215,'Liste de la paie'!$F$4:$F$14215,A15) -> 183235 | C15: 185000 | F15: =SUMIFS('Liste de la paie'!$H$4:$H14222,'Liste de la paie'!$A$4:$A14222,A15,'Liste de la paie'!$L$4:$L14222,"Payé") -> 182784 | G15: =SUMIFS('Liste de la paie'!$H$4:$H14222,'Liste de la paie'!$A$4:$A14222,A15,'Liste de la paie'!$L$4:$L14222,"Impayé") -> 451 | H15: =SUM(C15:E15)-F15 -> 2216
A16: 1Q11/2025 | B16: =SUMIFS('Liste de la paie'!$H$4:$H$14215,'Liste de la paie'!$F$4:$F$14215,A16) -> 204737 | C16: 208000 | F16: =SUMIFS('Liste de la paie'!$H$4:$H14223,'Liste de la paie'!$A$4:$A14223,A16,'Liste de la paie'!$L$4:$L14223,"Payé") -> 204737 | G16: =SUMIFS('Liste de la paie'!$H$4:$H14223,'Liste de la paie'!$A$4:$A14223,A16,'Liste de la paie'!$L$4:$L14223,"Impayé") -> 0 | H16: =SUM(C16:E16)-F16 -> 3263
A17: 2Q11/2025 | B17: =SUMIFS('Liste de la paie'!$H$4:$H$14215,'Liste de la paie'!$F$4:$F$14215,A17) -> 234051 | C17: 234000 | F17: =SUMIFS('Liste de la paie'!$H$4:$H14224,'Liste de la paie'!$A$4:$A14224,A17,'Liste de la paie'!$L$4:$L14224,"Payé") -> 233693 | G17: =SUMIFS('Liste de la paie'!$H$4:$H14224,'Liste de la paie'!$A$4:$A14224,A17,'Liste de la paie'!$L$4:$L14224,"Impayé") -> 358 | H17: =SUM(C17:E17)-F17 -> 307
A18: 1Q12/2025 | B18: =SUMIFS('Liste de la paie'!$H$4:$H$14215,'Liste de la paie'!$F$4:$F$14215,A18) -> 226083 | C18: 240000 | F18: =SUMIFS('Liste de la paie'!$H$4:$H14225,'Liste de la paie'!$A$4:$A14225,A18,'Liste de la paie'!$L$4:$L14225,"Payé") -> 225423 | G18: =SUMIFS('Liste de la paie'!$H$4:$H14225,'Liste de la paie'!$A$4:$A14225,A18,'Liste de la paie'!$L$4:$L14225,"Impayé") -> 660 | H18: =SUM(C18:E18)-F18 -> 14577
A19: 2Q12/2025 | B19: =SUMIFS('Liste de la paie'!$H$4:$H$14215,'Liste de la paie'!$F$4:$F$14215,A19) -> 178484 | C19: 190000 | F19: =SUMIFS('Liste de la paie'!$H$4:$H14226,'Liste de la paie'!$A$4:$A14226,A19,'Liste de la paie'!$L$4:$L14226,"Payé") -> 177762 | G19: =SUMIFS('Liste de la paie'!$H$4:$H14226,'Liste de la paie'!$A$4:$A14226,A19,'Liste de la paie'!$L$4:$L14226,"Impayé") -> 722 | H19: =SUM(C19:E19)-F19 -> 12238
A20: 1Q01/2026 | B20: =SUMIFS('Liste de la paie'!$H$4:$H$14215,'Liste de la paie'!$F$4:$F$14215,A20) -> 195919.58 | C20: 200000 | F20: =SUMIFS('Liste de la paie'!$H$4:$H14227,'Liste de la paie'!$A$4:$A14227,A20,'Liste de la paie'!$L$4:$L14227,"Payé") -> 195199.6 | G20: =SUMIFS('Liste de la paie'!$H$4:$H14227,'Liste de la paie'!$A$4:$A14227,A20,'Liste de la paie'!$L$4:$L14227,"Impayé") -> 719.98039 | H20: =SUM(C20:E20)-F20 -> 4800.3961
... A31: 2Q06/2026 | B31: =SUMIFS('Liste de la paie'!$H$4:$H$14215,'Liste de la paie'!$F$4:$F$14215,A31) -> 0 | C31: 0 | F31: =SUMIFS('Liste de la paie'!$H$4:$H14238,'Liste de la paie'!$A$4:$A14238,A31,'Liste de la paie'!$L$4:$L14238,"Payé") -> 0 | G31: =SUMIFS('Liste de la paie'!$H$4:$H14238,'Liste de la paie'!$A$4:$A14238,A31,'Liste de la paie'!$L$4:$L14238,"Impayé") -> 0 | H31: =SUM(C31:E31)-F31 -> 0
A32: TOTAL | B32: =SUM(B7:B31) -> 3271644.9 | C32: =SUM(C7:E31) -> 3164000 | F32: =SUM(F7:F31) -> 3187344.5 | G32: =SUM(G7:G31) -> 84300.379 | H32: =SUM(H7:H31) -> -23344.538
A41: Liste Des Ouvriers Impayé
A42: Liste Des Ouvriers Payé
A43: Liste De Tous Les Ouvriers
A44: Sommes Des Impayés

Sheet Liste de la paie
D1: Liste Des Ouvriers Impayé et payé 2025/2026
C2: =Récap!A44 -> Sommes Des Impayés | E2: =(SUM(Récap!B7:B31)-(SUM(Récap!F7:F31))) -> 84300.376
B3: Matricule | C3: Personnel | D3: Fonction | E3: Équipe | F3: Quinzaine | G3: Nbr de Jours | H3: Montant Net | I3: Date et Heure | L3: Statut | N3: la semaine
A4: 45838 | B4: 494 | C4: EL ACHAOUI ABDELHAMID | D4: OUVRIER | E4: BOUCHAT | F4: 45473 | G4: 8 | H4: 629.50942 | L4: =IF(ISBLANK(H4),"",IF(H4=K4,"Payé","Impayé")) -> Impayé
A5: 45838 | B5: 1355 | C5: EL KHAL FOUAD | D5: OUVRIER | E5: BOUCHAT | F5: 45473 | G5: 1 | H5: 71.535161 | L5: =IF(ISBLANK(H5),"",IF(H5=K5,"Payé","Impayé")) -> Impayé
A6: 45838 | B6: 1478 | C6: EL MANDOURI OMAR | D6: OUVRIER | E6: BOUCHAT | F6: 45473 | G6: 1 | H6: 71.535161 | L6: =IF(ISBLANK(H6),"",IF(H6=K6,"Payé","Impayé")) -> Impayé
A7: 45838 | B7: 1478 | C7: EL MANDOURI OMAR | D7: OUVRIER | E7: BOUCHAT | F7: 45473 | G7: 1 | H7: 71.535161 | L7: =IF(ISBLANK(H7),"",IF(H7=K7,"Payé","Impayé")) -> Impayé
A8: 45838 | B8: 1234 | C8: LANAYA MOUSTAPHA | D8: OUVRIER | E8: BOUCHAT | F8: 45473 | G8: 1 | H8: 78.688677 | L8: =IF(ISBLANK(H8),"",IF(H8=K8,"Payé","Impayé")) -> Impayé
A9: 45838 | B9: 3959 | C9: CHARKI ABDELLATIF | D9: OUVRIER | E9: ABAS | F9: 45473 | G9: 1 | H9: 83 | L9: =IF(ISBLANK(H9),"",IF(H9=K9,"Payé","Impayé")) -> Impayé
A10: 45838 | B10: 4021 | C10: EL ACHHAB MOHAMED | D10: OUVRIER | E10: ABAS | F10: 45473 | G10: 1 | H10: 83 | L10: =IF(ISBLANK(H10),"",IF(H10=K10,"Payé","Impayé")) -> Impayé
A11: 45838 | B11: 4080 | C11: AAMAR SOUFIANE | D11: OUVRIER | E11: ABAS | F11: 45473 | G11: 1 | H11: 83 | L11: =IF(ISBLANK(H11),"",IF(H11=K11,"Payé","Impayé")) -> Impayé
A12: 45838 | B12: 3508 | C12: AMIMI MUSTAPHA | D12: OUVRIER | E12: ABAS | F12: 45473 | G12: 5 | H12: 413 | L12: =IF(ISBLANK(H12),"",IF(H12=K12,"Payé","Impayé")) -> Impayé
A13: 45838 | B13: 4068 | C13: EL BADAOUY MOHAMED | D13: OUVRIER | E13: ABAS | F13: 45473 | G13: 1 | H13: 83 | L13: =IF(ISBLANK(H13),"",IF(H13=K13,"Payé","Impayé")) -> Impayé
A14: 45838 | B14: 4069 | C14: NACIRI KARIM | D14: OUVRIER | E14: ABAS | F14: 45473 | G14: 1 | H14: 83 | L14: =IF(ISBLANK(H14),"",IF(H14=K14,"Payé","Impayé")) -> Impayé
A15: 45838 | B15: 3949 | C15: ROUMAN IMAD | D15: OUVRIER | E15: ABAS | F15: 45473 | G15: 3 | H15: 248 | L15: =IF(ISBLANK(H15),"",IF(H15=K15,"Payé","Impayé")) -> Impayé
A16: 45838 | B16: 4016 | C16: SIYOUN YOUSSEF | D16: OUVRIER | E16: ABAS | F16: 45473 | G16: 1 | H16: 83 | L16: =IF(ISBLANK(H16),"",IF(H16=K16,"Payé","Impayé")) -> Impayé
A17: 45838 | B17: 3971 | C17: BOUDRAHI MOHAMED | D17: OUVRIER | E17: ABAS | F17: 1Q07/2024 | G17: 3 | H17: 248 | L17: =IF(ISBLANK(H17),"",IF(H17=K17,"Payé","Impayé")) -> Impayé
A18: 45838 | B18: 4167 | C18: DRISSI SAID | D18: OUVRIER | E18: ABAS | F18: 1Q07/2024 | G18: 1 | H18: 83 | L18: =IF(ISBLANK(H18),"",IF(H18=K18,"Payé","Impayé")) -> Impayé
A19: 45838 | B19: 5010 | C19: BOUHROUA MOUAD | D19: OUVRIER | E19: ABAS | F19: 1Q08/2024 | G19: 1 | H19: 83 | L19: =IF(ISBLANK(H19),"",IF(H19=K19,"Payé","Impayé")) -> Impayé
A20: 45838 | B20: 3822 | C20: M' SIAD ABDERRAHMAN | D20: OUVRIER | E20: ABAS | F20: 2Q07/2024 | G20: 1 | H20: 83 | L20: =IF(ISBLANK(H20),"",IF(H20=K20,"Payé","Impayé")) -> Impayé
A21: 45838 | B21: 4186 | C21: BEN M'BARKA ABDENNOUR | D21: OUVRIER | E21: ABAS | F21: 2Q07/2024 | G21: 1 | H21: 83 | L21: =IF(ISBLANK(H21),"",IF(H21=K21,"Payé","Impayé")) -> Impayé
A22: 45838 | B22: 4303 | C22: MSIAD EL HADI | D22: OUVRIER | E22: ABAS | F22: 2Q07/2024 | G22: 1 | H22: 83 | L22: =IF(ISBLANK(H22),"",IF(H22=K22,"Payé","Impayé")) -> Impayé
A23: 45838 | B23: 3119 | C23: GUERRAM AYOUB | D23: OUVRIER | E23: ABDELLAH | F23: 45473 | G23: 1 | H23: 78.688677 | L23: =IF(ISBLANK(H23),"",IF(H23=K23,"Payé","Impayé")) -> Impayé
A24: 45838 | B24: 3123 | C24: KHIRIBACH ABDERRAHIM | D24: OUVRIER | E24: ABDELLAH | F24: 45473 | G24: 1 | H24: 78.688677 | L24: =IF(ISBLANK(H24),"",IF(H24=K24,"Payé","Impayé")) -> Impayé
A25: 45838 | B25: 1261 | C25: RAHMOUNI HANAN | D25: OUVRIER | E25: AIN LAABID | F25: 45473 | G25: 3 | H25: 214.60548 | L25: =IF(ISBLANK(H25),"",IF(H25=K25,"Payé","Impayé")) -> Impayé
A26: 45838 | B26: 3102 | C26: SMAHAN CHAIBOUB | D26: OUVRIER | E26: ARBAOUA FEMME | F26: 45473 | G26: 1 | H26: 78.688677 | L26: =IF(ISBLANK(H26),"",IF(H26=K26,"Payé","Impayé")) -> Impayé
A27: 45838 | C27: AYOUB CHINGO | D27: OUVRIER | E27: ARBAOUA H | F27: 45473 | G27: 2 | H27: 143.07032 | L27: =IF(ISBLANK(H27),"",IF(H27=K27,"Payé","Impayé")) -> Impayé
A28: 45838 | C28: SEROKHE MOHAMED | D28: OUVRIER | E28: ARBAOUA H | F28: 45473 | G28: 1 | H28: 71.535161 | L28: =IF(ISBLANK(H28),"",IF(H28=K28,"Payé","Impayé")) -> Impayé
A29: 45838 | C29: TEHAMI KERIZI | D29: OUVRIER | E29: ARBAOUA H | F29: 45473 | G29: 1 | H29: 71.535161 | L29: =IF(ISBLANK(H29),"",IF(H29=K29,"Payé","Impayé")) -> Impayé
A30: 45838 | C30: YOUSSEF EL MARBOUH | D30: OUVRIER | E30: ARBAOUA H | F30: 45473 | G30: 1 | H30: 71.535161 | L30: =IF(ISBLANK(H30),"",IF(H30=K30,"Payé","Impayé")) -> Impayé
A31: 45838 | B31: 2372 | C31: ABDELLAOUI NAIMA | D31: OUVRIER | E31: ASSILA | F31: 45473 | G31: 1 | H31: 78.688677 | L31: =IF(ISBLANK(H31),"",IF(H31=K31,"Payé","Impayé")) -> Impayé
A32: 45838 | B32: 2430 | C32: ARABI JAMILA | D32: OUVRIER | E32: ASSILA | F32: 45473 | G32: 1 | H32: 78.688677 | L32: =IF(ISBLANK(H32),"",IF(H32=K32,"Payé","Impayé")) -> Impayé
A33: 45838 | B33: 2435 | C33: ASSILA LOUBNA | D33: OUVRIER | E33: ASSILA | F33: 45473 | G33: 2 | H33: 157.37735 | L33: =IF(ISBLANK(H33),"",IF(H33=K33,"Payé","Impayé")) -> Impayé
A34: 45838 | B34: 2364 | C34: BELKHADI WAFAE | D34: OUVRIER | E34: ASSILA | F34: 45473 | G34: 1 | H34: 78.688677 | L34: =IF(ISBLANK(H34),"",IF(H34=K34,"Payé","Impayé")) -> Impayé
A35: 45838 | B35: 2428 | C35: BEN TAHAR NISRENE | D35: OUVRIER | E35: ASSILA | F35: 45473 | G35: 2 | H35: 157.37735 | L35: =IF(ISBLANK(H35),"",IF(H35=K35,"Payé","Impayé")) -> Impayé
A36: 45838 | B36: 2363 | C36: EL AMERANI ZEHRA | D36: OUVRIER | E36: ASSILA | F36: 45473 | G36: 1 | H36: 78.688677 | L36: =IF(ISBLANK(H36),"",IF(H36=K36,"Payé","Impayé")) -> Impayé
A37: 45838 | B37: 2361 | C37: KHAOUDI HABIBA | D37: OUVRIER | E37: ASSILA | F37: 45473 | G37: 1 | H37: 78.688677 | L37: =IF(ISBLANK(H37),"",IF(H37=K37,"Payé","Impayé")) -> Impayé
A38: 45838 | B38: 2529 | C38: SOUFI ZEHOR | D38: OUVRIER | E38: ASSILA | F38: 45473 | G38: 1 | H38: 78.688677 | L38: =IF(ISBLANK(H38),"",IF(H38=K38,"Payé","Impayé")) -> Impayé
A39: 45838 | B39: 1277 | C39: BAAL HIND | D39: OUVRIER | E39: AYOUB | F39: 45473 | G39: 3 | H39: 215 | L39: =IF(ISBLANK(H39),"",IF(H39=K39,"Payé","Impayé")) -> Impayé
A40: 45838 | B40: 2926 | C40: EL FATEHY MOHAMED | D40: OUVRIER | E40: BACHIR ,H | F40: 45473 | G40: 1 | H40: 83 | L40: =IF(ISBLANK(H40),"",IF(H40=K40,"Payé","Impayé")) -> Impayé
...

Sheet ETAT EMARGEMENT
A1: ETAT D'EMARGEMENT
D3: 1ér QNZ aout
A4: MATRICULE | B4: NOM ET PRENOM | C4: EQUIPE | D4: NBR JOURS | E4: MONTANT | F4: SINGATURE
A5: 3412 | B5: EL HMAR SAID | C5: AVC | D5: 2 | E5: 173
A6: 3607 | B6: HAMDOUCH JAOUAD | C6: BGF | D6: 12 | E6: 1201
A7: 3672 | B7: SIKI AHMED | C7: BGF | D7: 16 | E7: 1769
A8: 6 | B8: EL KARA HAMZA | C8: BGF | D8: 16 | E8: 1687
A9: 41 | B9: EL HLIMI ABDRRAHIM | C9: BGF | D9: 14 | E9: 1415
A10: 95 | B10: EL MESBAHI AHMED | C10: BGF 1 | D10: 16 | E10: 1617
A11: 4373 | B11: NEHAILI ADIL | C11: BGF 1 | D11: 14 | E11: 1354
A12: 4807 | B12: EL HADMI MUSTAPHA | C12: BGF 1 | D12: 13 | E12: 1258
A13: 198 | B13: EL MAJDOUBI HAMID | C13: BGF 3 | D13: 16 | E13: 1617
A14: 202 | B14: EL BERRAITI DRISS | C14: BGF 3 | D14: 14 | E14: 1415
A15: 752 | B15: AHDOUD HICHAM | C15: BGF 4 | D15: 14 | E15: 1415
A16: 753 | B16: HILI NORDDINE | C16: BGF 4 | D16: 14 | E16: 1415
... A51: 5340 | B51: EL LKHATYBY MAROUAN | C51: BOUACHAT | D51: 4 | E51: 347
B52: EL MAHJOUBI ABDGHAFOUR | C52: BOUACHAT | D52: 171 | E52: 4275
A53: 346 | B53: TOUATI KHADOUJ | C53: BOUCHAREN | D53: 9 | E53: 820
A54: 348 | B54: EL HRAOUIYA KARIMA | C54: BOUCHAREN | D54: 12 | E54: 1285
A55: 354 | B55: NACIRI FATNA | C55: BOUCHAREN | D55: 7 | E55: 638
A56: 360 | B56: EL MAAROUFI HAFIDA | C56: BOUCHAREN | D56: 9 | E56: 964
A57: 520 | B57: AL MGITNI FATNA | C57: BOUCHAREN | D57: 9 | E57: 820
A58: 521 | B58: BOUMEDIAN FATOUM | C58: BOUCHAREN | D58: 9 | E58: 820
A59: 559 | B59: SOUIR FATIMA | C59: BOUCHAREN | D59: 7 | E59: 638
A60: 845 | B60: AJCHEF KHADIJA | C60: BOUCHAREN | D60: 9 | E60: 820
A61: 1278 | B61: BOUTBAILA SMAHANE | C61: BOUCHAREN | D61: 6 | E61: 546
A62: 1593 | B62: EL AHRACH ASSMAHAN | C62: BOUCHAREN | D62: 8 | E62: 694
A63: 1723 | B63: EL MAAROUFI MOHAMED | C63: BOUCHAREN | D63: 15 | E63: 1536
A64: 2664 | B64: EL HAROUIYA MENANA | C64: BOUCHAREN | D64: 8 | E64: 694
... A68: 3726 | B68: HAMDOUCH FATIMA ZOHRA | C68: BOUCHAREN | D68: 9 | E68: 781
A69: TRS308 | B69: EL MGHITNI MOUSTAPHA | C69: BOUCHAREN | D69: 163 | E69: 4075
A70: 3427 | B70: AYAD ASMAE | C70: BOUCHAREN | D70: 9 | E70: 781
A71: 4415 | B71: EL HAMRI FARAH | C71: BOUCHAREN | D71: 4 | E71: 347
A72: 4550 | B72: HAMDOUCH IBTISSAM | C72: BOUCHAREN | D72: 8 | E72: 694
A73: 5268 | B73: EL BOUALI DOUAE | C73: BOUCHAREN | D73: 7 | E73: 607
A74: 5274 | B74: BOUACHA FATIMA ZOHRA | C74: BOUCHAREN | D74: 5 | E74: 434
A75: 2580 | B75: EL FRAIHI FATIMA | C75: CHAHDI | D75: 1 | E75: 87
A76: 2589 | B76: BOUMEDIAN NAJEOI | C76: CHAHDI | D76: 4 | E76: 347
A77: 5187 | B77: WAFAE LAKEHAL | C77: CHAHDI | D77: 6 | E77: 520
A78: 5225 | B78: BOUTAHRA AICHA | C78: CHAHDI | D78: 2 | E78: 173
...

Sheet PV de la Paie
A5: PV DE PAIEMENT
A8: DATE | C8: HEURE DEBUT | D8: LIEU | F8: MONTANT Payé | G8: NOM ET Prénom | H8: AGENT DE PAIEMENT | I8: REMARQUES
A9: 2Q04/2025 | B9: 2Q04/2025 | C9: 0.59375 | D9: Berry Good Farms | F9: 400 | G9: EL UAHEDE MOHAMED | H9: ACHRAF EL INAK | I9: ****
A12: ACHRAF EL INAK | F12: HAMZA ALLAOUI
H14: Larache Le : | I14: 46079
