Workbook

Sheet Total
A1: Matricule | B1: Personnel | C1: Variété | D1: 16 | E1: 17 | F1: 18 | G1: 19 | H1: 20 | I1: 21 | J1: 22 | K1: 23 | L1: 24 | M1: 25 | N1: 26 | O1: 27 | P1: 28 | Q1: 29 | R1: 30 | S1: Total | U1: Matricule | V1: Personnel | W1: Variété | X1: 16 | Y1: 17 | Z1: 18 | AA1: 19 | AB1: 20 | AC1: 21 | AD1: 22 | AE1: 23 | AF1: 24 | AG1: 25 | AH1: 26 | AI1: 27 | AJ1: 28 | AK1: 29 | AL1: 30 | AM1: Total
A2: AQ10810 | B2: AYADI FATIHA | C2: MARAVILLA | S2: =SUM(D2:R2) -> 0 | T2: 1 | U2: AQ10810 | V2: AYADI FATIHA | W2: MARAVILLA | X2: =IF(D2<20,0,IF(D2<25,20,IF(D2<30,40,IF(D2<=40,60+(D2-30)*3,60+30+(D2-40)*4)))) -> 0 | Y2: =IF(E2<20,0,IF(E2<25,20,IF(E2<30,40,IF(E2<=40,60+(E2-30)*3,60+30+(E2-40)*4)))) -> 0 | Z2: =IF(F2<20,0,IF(F2<25,20,IF(F2<30,40,IF(F2<=40,60+(F2-30)*3,60+30+(F2-40)*4)))) -> 0 | AA2: =IF(G2<20,0,IF(G2<25,20,IF(G2<30,40,IF(G2<=40,60+(G2-30)*3,60+30+(G2-40)*4)))) -> 0 | AB2: =IF(H2<20,0,IF(H2<25,20,IF(H2<30,40,IF(H2<=40,60+(H2-30)*3,60+30+(H2-40)*4)))) -> 0 | AC2: =IF(I2<20,0,IF(I2<25,20,IF(I2<30,40,IF(I2<=40,60+(I2-30)*3,60+30+(I2-40)*4)))) -> 0 | AD2: =IF(J2<20,0,IF(J2<25,20,IF(J2<30,40,IF(J2<=40,60+(J2-30)*3,60+30+(J2-40)*4)))) -> 0 | AE2: =IF(K2<20,0,IF(K2<25,20,IF(K2<30,40,IF(K2<=40,60+(K2-30)*3,60+30+(K2-40)*4)))) -> 0 | ... AL2: =IF(R2<20,0,IF(R2<25,20,IF(R2<30,40,IF(R2<=40,60+(R2-30)*3,60+30+(R2-40)*4)))) -> 0 | AM2: =SUM(X2:AL2) -> 0
A3: AQ10811 | B3: HOUSNIYA EL KHELIFA | C3: MARAVILLA | S3: =SUM(D3:R3) -> 0 | T3: 1 | U3: AQ10811 | V3: HOUSNIYA EL KHELIFA | W3: MARAVILLA | X3: =IF(D3<20,0,IF(D3<25,20,IF(D3<30,40,IF(D3<=40,60+(D3-30)*3,60+30+(D3-40)*4)))) -> 0 | Y3: =IF(E3<20,0,IF(E3<25,20,IF(E3<30,40,IF(E3<=40,60+(E3-30)*3,60+30+(E3-40)*4)))) -> 0 | Z3: =IF(F3<20,0,IF(F3<25,20,IF(F3<30,40,IF(F3<=40,60+(F3-30)*3,60+30+(F3-40)*4)))) -> 0 | AA3: =IF(G3<20,0,IF(G3<25,20,IF(G3<30,40,IF(G3<=40,60+(G3-30)*3,60+30+(G3-40)*4)))) -> 0 | AB3: =IF(H3<20,0,IF(H3<25,20,IF(H3<30,40,IF(H3<=40,60+(H3-30)*3,60+30+(H3-40)*4)))) -> 0 | AC3: =IF(I3<20,0,IF(I3<25,20,IF(I3<30,40,IF(I3<=40,60+(I3-30)*3,60+30+(I3-40)*4)))) -> 0 | AD3: =IF(J3<20,0,IF(J3<25,20,IF(J3<30,40,IF(J3<=40,60+(J3-30)*3,60+30+(J3-40)*4)))) -> 0 | AE3: =IF(K3<20,0,IF(K3<25,20,IF(K3<30,40,IF(K3<=40,60+(K3-30)*3,60+30+(K3-40)*4)))) -> 0 | ... AL3: =IF(R3<20,0,IF(R3<25,20,IF(R3<30,40,IF(R3<=40,60+(R3-30)*3,60+30+(R3-40)*4)))) -> 0 | AM3: =SUM(X3:AL3) -> 0
A4: AQ10812 | B4: EL CHAMSI ZOUHRA | C4: MARAVILLA | S4: =SUM(D4:R4) -> 0 | T4: 1 | U4: AQ10812 | V4: EL CHAMSI ZOUHRA | W4: MARAVILLA | X4: =IF(D4<20,0,IF(D4<25,20,IF(D4<30,40,IF(D4<=40,60+(D4-30)*3,60+30+(D4-40)*4)))) -> 0 | Y4: =IF(E4<20,0,IF(E4<25,20,IF(E4<30,40,IF(E4<=40,60+(E4-30)*3,60+30+(E4-40)*4)))) -> 0 | Z4: =IF(F4<20,0,IF(F4<25,20,IF(F4<30,40,IF(F4<=40,60+(F4-30)*3,60+30+(F4-40)*4)))) -> 0 | AA4: =IF(G4<20,0,IF(G4<25,20,IF(G4<30,40,IF(G4<=40,60+(G4-30)*3,60+30+(G4-40)*4)))) -> 0 | AB4: =IF(H4<20,0,IF(H4<25,20,IF(H4<30,40,IF(H4<=40,60+(H4-30)*3,60+30+(H4-40)*4)))) -> 0 | AC4: =IF(I4<20,0,IF(I4<25,20,IF(I4<30,40,IF(I4<=40,60+(I4-30)*3,60+30+(I4-40)*4)))) -> 0 | AD4: =IF(J4<20,0,IF(J4<25,20,IF(J4<30,40,IF(J4<=40,60+(J4-30)*3,60+30+(J4-40)*4)))) -> 0 | AE4: =IF(K4<20,0,IF(K4<25,20,IF(K4<30,40,IF(K4<=40,60+(K4-30)*3,60+30+(K4-40)*4)))) -> 0 | ... AL4: =IF(R4<20,0,IF(R4<25,20,IF(R4<30,40,IF(R4<=40,60+(R4-30)*3,60+30+(R4-40)*4)))) -> 0 | AM4: =SUM(X4:AL4) -> 0
A5: AQ10813 | B5: EL JAMAL KHAADIJA | C5: MARAVILLA | S5: =SUM(D5:R5) -> 0 | T5: 1 | U5: AQ10813 | V5: EL JAMAL KHAADIJA | W5: MARAVILLA | X5: =IF(D5<20,0,IF(D5<25,20,IF(D5<30,40,IF(D5<=40,60+(D5-30)*3,60+30+(D5-40)*4)))) -> 0 | Y5: =IF(E5<20,0,IF(E5<25,20,IF(E5<30,40,IF(E5<=40,60+(E5-30)*3,60+30+(E5-40)*4)))) -> 0 | Z5: =IF(F5<20,0,IF(F5<25,20,IF(F5<30,40,IF(F5<=40,60+(F5-30)*3,60+30+(F5-40)*4)))) -> 0 | AA5: =IF(G5<20,0,IF(G5<25,20,IF(G5<30,40,IF(G5<=40,60+(G5-30)*3,60+30+(G5-40)*4)))) -> 0 | AB5: =IF(H5<20,0,IF(H5<25,20,IF(H5<30,40,IF(H5<=40,60+(H5-30)*3,60+30+(H5-40)*4)))) -> 0 | AC5: =IF(I5<20,0,IF(I5<25,20,IF(I5<30,40,IF(I5<=40,60+(I5-30)*3,60+30+(I5-40)*4)))) -> 0 | AD5: =IF(J5<20,0,IF(J5<25,20,IF(J5<30,40,IF(J5<=40,60+(J5-30)*3,60+30+(J5-40)*4)))) -> 0 | AE5: =IF(K5<20,0,IF(K5<25,20,IF(K5<30,40,IF(K5<=40,60+(K5-30)*3,60+30+(K5-40)*4)))) -> 0 | ... AL5: =IF(R5<20,0,IF(R5<25,20,IF(R5<30,40,IF(R5<=40,60+(R5-30)*3,60+30+(R5-40)*4)))) -> 0 | AM5: =SUM(X5:AL5) -> 0
A6: AQ10814 | B6: EL ZAIME FATIMA ZOHRA | C6: MARAVILLA | S6: =SUM(D6:R6) -> 0 | T6: 1 | U6: AQ10814 | V6: EL ZAIME FATIMA ZOHRA | W6: MARAVILLA | X6: =IF(D6<20,0,IF(D6<25,20,IF(D6<30,40,IF(D6<=40,60+(D6-30)*3,60+30+(D6-40)*4)))) -> 0 | Y6: =IF(E6<20,0,IF(E6<25,20,IF(E6<30,40,IF(E6<=40,60+(E6-30)*3,60+30+(E6-40)*4)))) -> 0 | Z6: =IF(F6<20,0,IF(F6<25,20,IF(F6<30,40,IF(F6<=40,60+(F6-30)*3,60+30+(F6-40)*4)))) -> 0 | AA6: =IF(G6<20,0,IF(G6<25,20,IF(G6<30,40,IF(G6<=40,60+(G6-30)*3,60+30+(G6-40)*4)))) -> 0 | AB6: =IF(H6<20,0,IF(H6<25,20,IF(H6<30,40,IF(H6<=40,60+(H6-30)*3,60+30+(H6-40)*4)))) -> 0 | AC6: =IF(I6<20,0,IF(I6<25,20,IF(I6<30,40,IF(I6<=40,60+(I6-30)*3,60+30+(I6-40)*4)))) -> 0 | AD6: =IF(J6<20,0,IF(J6<25,20,IF(J6<30,40,IF(J6<=40,60+(J6-30)*3,60+30+(J6-40)*4)))) -> 0 | AE6: =IF(K6<20,0,IF(K6<25,20,IF(K6<30,40,IF(K6<=40,60+(K6-30)*3,60+30+(K6-40)*4)))) -> 0 | ... AL6: =IF(R6<20,0,IF(R6<25,20,IF(R6<30,40,IF(R6<=40,60+(R6-30)*3,60+30+(R6-40)*4)))) -> 0 | AM6: =SUM(X6:AL6) -> 0
A7: AQ10815 | B7: EL REGAD HIND | C7: MARAVILLA | S7: =SUM(D7:R7) -> 0 | T7: 1 | U7: AQ10815 | V7: EL REGAD HIND | W7: MARAVILLA | X7: =IF(D7<20,0,IF(D7<25,20,IF(D7<30,40,IF(D7<=40,60+(D7-30)*3,60+30+(D7-40)*4)))) -> 0 | Y7: =IF(E7<20,0,IF(E7<25,20,IF(E7<30,40,IF(E7<=40,60+(E7-30)*3,60+30+(E7-40)*4)))) -> 0 | Z7: =IF(F7<20,0,IF(F7<25,20,IF(F7<30,40,IF(F7<=40,60+(F7-30)*3,60+30+(F7-40)*4)))) -> 0 | AA7: =IF(G7<20,0,IF(G7<25,20,IF(G7<30,40,IF(G7<=40,60+(G7-30)*3,60+30+(G7-40)*4)))) -> 0 | AB7: =IF(H7<20,0,IF(H7<25,20,IF(H7<30,40,IF(H7<=40,60+(H7-30)*3,60+30+(H7-40)*4)))) -> 0 | AC7: =IF(I7<20,0,IF(I7<25,20,IF(I7<30,40,IF(I7<=40,60+(I7-30)*3,60+30+(I7-40)*4)))) -> 0 | AD7: =IF(J7<20,0,IF(J7<25,20,IF(J7<30,40,IF(J7<=40,60+(J7-30)*3,60+30+(J7-40)*4)))) -> 0 | AE7: =IF(K7<20,0,IF(K7<25,20,IF(K7<30,40,IF(K7<=40,60+(K7-30)*3,60+30+(K7-40)*4)))) -> 0 | ... AL7: =IF(R7<20,0,IF(R7<25,20,IF(R7<30,40,IF(R7<=40,60+(R7-30)*3,60+30+(R7-40)*4)))) -> 0 | AM7: =SUM(X7:AL7) -> 0
A8: AQ10816 | B8: AL ABDI BOUCHRA | C8: MARAVILLA | S8: =SUM(D8:R8) -> 0 | T8: 1 | U8: AQ10816 | V8: AL ABDI BOUCHRA | W8: MARAVILLA | X8: =IF(D8<20,0,IF(D8<25,20,IF(D8<30,40,IF(D8<=40,60+(D8-30)*3,60+30+(D8-40)*4)))) -> 0 | Y8: =IF(E8<20,0,IF(E8<25,20,IF(E8<30,40,IF(E8<=40,60+(E8-30)*3,60+30+(E8-40)*4)))) -> 0 | Z8: =IF(F8<20,0,IF(F8<25,20,IF(F8<30,40,IF(F8<=40,60+(F8-30)*3,60+30+(F8-40)*4)))) -> 0 | AA8: =IF(G8<20,0,IF(G8<25,20,IF(G8<30,40,IF(G8<=40,60+(G8-30)*3,60+30+(G8-40)*4)))) -> 0 | AB8: =IF(H8<20,0,IF(H8<25,20,IF(H8<30,40,IF(H8<=40,60+(H8-30)*3,60+30+(H8-40)*4)))) -> 0 | AC8: =IF(I8<20,0,IF(I8<25,20,IF(I8<30,40,IF(I8<=40,60+(I8-30)*3,60+30+(I8-40)*4)))) -> 0 | AD8: =IF(J8<20,0,IF(J8<25,20,IF(J8<30,40,IF(J8<=40,60+(J8-30)*3,60+30+(J8-40)*4)))) -> 0 | AE8: =IF(K8<20,0,IF(K8<25,20,IF(K8<30,40,IF(K8<=40,60+(K8-30)*3,60+30+(K8-40)*4)))) -> 0 | ... AL8: =IF(R8<20,0,IF(R8<25,20,IF(R8<30,40,IF(R8<=40,60+(R8-30)*3,60+30+(R8-40)*4)))) -> 0 | AM8: =SUM(X8:AL8) -> 0
A9: CA10539 | B9: BENAYAD ASSIA | C9: MARAVILLA | S9: =SUM(D9:R9) -> 0 | T9: 1 | U9: CA10539 | V9: BENAYAD ASSIA | W9: MARAVILLA | X9: =IF(D9<20,0,IF(D9<25,20,IF(D9<30,40,IF(D9<=40,60+(D9-30)*3,60+30+(D9-40)*4)))) -> 0 | Y9: =IF(E9<20,0,IF(E9<25,20,IF(E9<30,40,IF(E9<=40,60+(E9-30)*3,60+30+(E9-40)*4)))) -> 0 | Z9: =IF(F9<20,0,IF(F9<25,20,IF(F9<30,40,IF(F9<=40,60+(F9-30)*3,60+30+(F9-40)*4)))) -> 0 | AA9: =IF(G9<20,0,IF(G9<25,20,IF(G9<30,40,IF(G9<=40,60+(G9-30)*3,60+30+(G9-40)*4)))) -> 0 | AB9: =IF(H9<20,0,IF(H9<25,20,IF(H9<30,40,IF(H9<=40,60+(H9-30)*3,60+30+(H9-40)*4)))) -> 0 | AC9: =IF(I9<20,0,IF(I9<25,20,IF(I9<30,40,IF(I9<=40,60+(I9-30)*3,60+30+(I9-40)*4)))) -> 0 | AD9: =IF(J9<20,0,IF(J9<25,20,IF(J9<30,40,IF(J9<=40,60+(J9-30)*3,60+30+(J9-40)*4)))) -> 0 | AE9: =IF(K9<20,0,IF(K9<25,20,IF(K9<30,40,IF(K9<=40,60+(K9-30)*3,60+30+(K9-40)*4)))) -> 0 | ... AL9: =IF(R9<20,0,IF(R9<25,20,IF(R9<30,40,IF(R9<=40,60+(R9-30)*3,60+30+(R9-40)*4)))) -> 0 | AM9: =SUM(X9:AL9) -> 0
A10: CA10565 | B10: EL HAMAMI ZAKIA | C10: MARAVILLA | D10: 9 | E10: 9 | F10: 9 | G10: 10.5 | H10: 7.5 | J10: 39 | K10: 40.5 | L10: 57 | M10: 63 | S10: =SUM(D10:R10) -> 244.5 | T10: 1 | U10: CA10565 | V10: EL HAMAMI ZAKIA | W10: MARAVILLA | X10: =IF(D10<20,0,IF(D10<25,20,IF(D10<30,40,IF(D10<=40,60+(D10-30)*3,60+30+(D10-40)*4)))) -> 0 | Y10: =IF(E10<20,0,IF(E10<25,20,IF(E10<30,40,IF(E10<=40,60+(E10-30)*3,60+30+(E10-40)*4)))) -> 0 | Z10: =IF(F10<20,0,IF(F10<25,20,IF(F10<30,40,IF(F10<=40,60+(F10-30)*3,60+30+(F10-40)*4)))) -> 0 | AA10: =IF(G10<20,0,IF(G10<25,20,IF(G10<30,40,IF(G10<=40,60+(G10-30)*3,60+30+(G10-40)*4)))) -> 0 | AB10: =IF(H10<20,0,IF(H10<25,20,IF(H10<30,40,IF(H10<=40,60+(H10-30)*3,60+30+(H10-40)*4)))) -> 0 | AC10: =IF(I10<20,0,IF(I10<25,20,IF(I10<30,40,IF(I10<=40,60+(I10-30)*3,60+30+(I10-40)*4)))) -> 0 | AD10: =IF(J10<20,0,IF(J10<25,20,IF(J10<30,40,IF(J10<=40,60+(J10-30)*3,60+30+(J10-40)*4)))) -> 87 | AE10: =IF(K10<20,0,IF(K10<25,20,IF(K10<30,40,IF(K10<=40,60+(K10-30)*3,60+30+(K10-40)*4)))) -> 92 | ... AL10: =IF(R10<20,0,IF(R10<25,20,IF(R10<30,40,IF(R10<=40,60+(R10-30)*3,60+30+(R10-40)*4)))) -> 0 | AM10: =SUM(X10:AL10) -> 519
A11: CA10566 | B11: REGRAGUI GHITA | C11: MARAVILLA | D11: 9 | E11: 7.5 | F11: 9 | G11: 12 | I11: 22.5 | J11: 25.5 | K11: 39 | L11: 49.5 | M11: 51 | S11: =SUM(D11:R11) -> 225 | T11: 1 | U11: CA10566 | V11: REGRAGUI GHITA | W11: MARAVILLA | X11: =IF(D11<20,0,IF(D11<25,20,IF(D11<30,40,IF(D11<=40,60+(D11-30)*3,60+30+(D11-40)*4)))) -> 0 | Y11: =IF(E11<20,0,IF(E11<25,20,IF(E11<30,40,IF(E11<=40,60+(E11-30)*3,60+30+(E11-40)*4)))) -> 0 | Z11: =IF(F11<20,0,IF(F11<25,20,IF(F11<30,40,IF(F11<=40,60+(F11-30)*3,60+30+(F11-40)*4)))) -> 0 | AA11: =IF(G11<20,0,IF(G11<25,20,IF(G11<30,40,IF(G11<=40,60+(G11-30)*3,60+30+(G11-40)*4)))) -> 0 | AB11: =IF(H11<20,0,IF(H11<25,20,IF(H11<30,40,IF(H11<=40,60+(H11-30)*3,60+30+(H11-40)*4)))) -> 0 | AC11: =IF(I11<20,0,IF(I11<25,20,IF(I11<30,40,IF(I11<=40,60+(I11-30)*3,60+30+(I11-40)*4)))) -> 20 | AD11: =IF(J11<20,0,IF(J11<25,20,IF(J11<30,40,IF(J11<=40,60+(J11-30)*3,60+30+(J11-40)*4)))) -> 40 | AE11: =IF(K11<20,0,IF(K11<25,20,IF(K11<30,40,IF(K11<=40,60+(K11-30)*3,60+30+(K11-40)*4)))) -> 87 | ... AL11: =IF(R11<20,0,IF(R11<25,20,IF(R11<30,40,IF(R11<=40,60+(R11-30)*3,60+30+(R11-40)*4)))) -> 0 | AM11: =SUM(X11:AL11) -> 409
A12: CA10567 | B12: FERJANI ZOUHRA | C12: MARAVILLA | E12: 6 | F12: 6 | G12: 9 | H12: 4.5 | M12: 33 | S12: =SUM(D12:R12) -> 58.5 | T12: 1 | U12: CA10567 | V12: FERJANI ZOUHRA | W12: MARAVILLA | X12: =IF(D12<20,0,IF(D12<25,20,IF(D12<30,40,IF(D12<=40,60+(D12-30)*3,60+30+(D12-40)*4)))) -> 0 | Y12: =IF(E12<20,0,IF(E12<25,20,IF(E12<30,40,IF(E12<=40,60+(E12-30)*3,60+30+(E12-40)*4)))) -> 0 | Z12: =IF(F12<20,0,IF(F12<25,20,IF(F12<30,40,IF(F12<=40,60+(F12-30)*3,60+30+(F12-40)*4)))) -> 0 | AA12: =IF(G12<20,0,IF(G12<25,20,IF(G12<30,40,IF(G12<=40,60+(G12-30)*3,60+30+(G12-40)*4)))) -> 0 | AB12: =IF(H12<20,0,IF(H12<25,20,IF(H12<30,40,IF(H12<=40,60+(H12-30)*3,60+30+(H12-40)*4)))) -> 0 | AC12: =IF(I12<20,0,IF(I12<25,20,IF(I12<30,40,IF(I12<=40,60+(I12-30)*3,60+30+(I12-40)*4)))) -> 0 | AD12: =IF(J12<20,0,IF(J12<25,20,IF(J12<30,40,IF(J12<=40,60+(J12-30)*3,60+30+(J12-40)*4)))) -> 0 | AE12: =IF(K12<20,0,IF(K12<25,20,IF(K12<30,40,IF(K12<=40,60+(K12-30)*3,60+30+(K12-40)*4)))) -> 0 | ... AL12: =IF(R12<20,0,IF(R12<25,20,IF(R12<30,40,IF(R12<=40,60+(R12-30)*3,60+30+(R12-40)*4)))) -> 0 | AM12: =SUM(X12:AL12) -> 69
A13: CA10569 | B13: EL BOUAINI ABDENBI | C13: MARAVILLA | K13: 19.5 | L13: 48 | M13: 40.5 | S13: =SUM(D13:R13) -> 108 | T13: 1 | U13: CA10569 | V13: EL BOUAINI ABDENBI | W13: MARAVILLA | X13: =IF(D13<20,0,IF(D13<25,20,IF(D13<30,40,IF(D13<=40,60+(D13-30)*3,60+30+(D13-40)*4)))) -> 0 | Y13: =IF(E13<20,0,IF(E13<25,20,IF(E13<30,40,IF(E13<=40,60+(E13-30)*3,60+30+(E13-40)*4)))) -> 0 | Z13: =IF(F13<20,0,IF(F13<25,20,IF(F13<30,40,IF(F13<=40,60+(F13-30)*3,60+30+(F13-40)*4)))) -> 0 | AA13: =IF(G13<20,0,IF(G13<25,20,IF(G13<30,40,IF(G13<=40,60+(G13-30)*3,60+30+(G13-40)*4)))) -> 0 | AB13: =IF(H13<20,0,IF(H13<25,20,IF(H13<30,40,IF(H13<=40,60+(H13-30)*3,60+30+(H13-40)*4)))) -> 0 | AC13: =IF(I13<20,0,IF(I13<25,20,IF(I13<30,40,IF(I13<=40,60+(I13-30)*3,60+30+(I13-40)*4)))) -> 0 | AD13: =IF(J13<20,0,IF(J13<25,20,IF(J13<30,40,IF(J13<=40,60+(J13-30)*3,60+30+(J13-40)*4)))) -> 0 | AE13: =IF(K13<20,0,IF(K13<25,20,IF(K13<30,40,IF(K13<=40,60+(K13-30)*3,60+30+(K13-40)*4)))) -> 0 | ... AL13: =IF(R13<20,0,IF(R13<25,20,IF(R13<30,40,IF(R13<=40,60+(R13-30)*3,60+30+(R13-40)*4)))) -> 0 | AM13: =SUM(X13:AL13) -> 214
A14: CA10657 | B14: EL HAMAMI MOHAMED | C14: MARAVILLA | K14: 19.5 | L14: 27 | S14: =SUM(D14:R14) -> 46.5 | T14: 1 | U14: CA10657 | V14: EL HAMAMI MOHAMED | W14: MARAVILLA | X14: =IF(D14<20,0,IF(D14<25,20,IF(D14<30,40,IF(D14<=40,60+(D14-30)*3,60+30+(D14-40)*4)))) -> 0 | Y14: =IF(E14<20,0,IF(E14<25,20,IF(E14<30,40,IF(E14<=40,60+(E14-30)*3,60+30+(E14-40)*4)))) -> 0 | Z14: =IF(F14<20,0,IF(F14<25,20,IF(F14<30,40,IF(F14<=40,60+(F14-30)*3,60+30+(F14-40)*4)))) -> 0 | AA14: =IF(G14<20,0,IF(G14<25,20,IF(G14<30,40,IF(G14<=40,60+(G14-30)*3,60+30+(G14-40)*4)))) -> 0 | AB14: =IF(H14<20,0,IF(H14<25,20,IF(H14<30,40,IF(H14<=40,60+(H14-30)*3,60+30+(H14-40)*4)))) -> 0 | AC14: =IF(I14<20,0,IF(I14<25,20,IF(I14<30,40,IF(I14<=40,60+(I14-30)*3,60+30+(I14-40)*4)))) -> 0 | AD14: =IF(J14<20,0,IF(J14<25,20,IF(J14<30,40,IF(J14<=40,60+(J14-30)*3,60+30+(J14-40)*4)))) -> 0 | AE14: =IF(K14<20,0,IF(K14<25,20,IF(K14<30,40,IF(K14<=40,60+(K14-30)*3,60+30+(K14-40)*4)))) -> 0 | ... AL14: =IF(R14<20,0,IF(R14<25,20,IF(R14<30,40,IF(R14<=40,60+(R14-30)*3,60+30+(R14-40)*4)))) -> 0 | AM14: =SUM(X14:AL14) -> 40
A15: CA10700 | B15: HAFOUDA ILIYASS | C15: MARAVILLA | S15: =SUM(D15:R15) -> 0 | T15: 1 | U15: CA10700 | V15: HAFOUDA ILIYASS | W15: MARAVILLA | X15: =IF(D15<20,0,IF(D15<25,20,IF(D15<30,40,IF(D15<=40,60+(D15-30)*3,60+30+(D15-40)*4)))) -> 0 | Y15: =IF(E15<20,0,IF(E15<25,20,IF(E15<30,40,IF(E15<=40,60+(E15-30)*3,60+30+(E15-40)*4)))) -> 0 | Z15: =IF(F15<20,0,IF(F15<25,20,IF(F15<30,40,IF(F15<=40,60+(F15-30)*3,60+30+(F15-40)*4)))) -> 0 | AA15: =IF(G15<20,0,IF(G15<25,20,IF(G15<30,40,IF(G15<=40,60+(G15-30)*3,60+30+(G15-40)*4)))) -> 0 | AB15: =IF(H15<20,0,IF(H15<25,20,IF(H15<30,40,IF(H15<=40,60+(H15-30)*3,60+30+(H15-40)*4)))) -> 0 | AC15: =IF(I15<20,0,IF(I15<25,20,IF(I15<30,40,IF(I15<=40,60+(I15-30)*3,60+30+(I15-40)*4)))) -> 0 | AD15: =IF(J15<20,0,IF(J15<25,20,IF(J15<30,40,IF(J15<=40,60+(J15-30)*3,60+30+(J15-40)*4)))) -> 0 | AE15: =IF(K15<20,0,IF(K15<25,20,IF(K15<30,40,IF(K15<=40,60+(K15-30)*3,60+30+(K15-40)*4)))) -> 0 | ... AL15: =IF(R15<20,0,IF(R15<25,20,IF(R15<30,40,IF(R15<=40,60+(R15-30)*3,60+30+(R15-40)*4)))) -> 0 | AM15: =SUM(X15:AL15) -> 0
A16: CA10755 | B16: ASSILA KARIM | C16: MARAVILLA | K16: 15 | L16: 48 | M16: 36 | S16: =SUM(D16:R16) -> 99 | T16: 1 | U16: CA10755 | V16: ASSILA KARIM | W16: MARAVILLA | X16: =IF(D16<20,0,IF(D16<25,20,IF(D16<30,40,IF(D16<=40,60+(D16-30)*3,60+30+(D16-40)*4)))) -> 0 | Y16: =IF(E16<20,0,IF(E16<25,20,IF(E16<30,40,IF(E16<=40,60+(E16-30)*3,60+30+(E16-40)*4)))) -> 0 | Z16: =IF(F16<20,0,IF(F16<25,20,IF(F16<30,40,IF(F16<=40,60+(F16-30)*3,60+30+(F16-40)*4)))) -> 0 | AA16: =IF(G16<20,0,IF(G16<25,20,IF(G16<30,40,IF(G16<=40,60+(G16-30)*3,60+30+(G16-40)*4)))) -> 0 | AB16: =IF(H16<20,0,IF(H16<25,20,IF(H16<30,40,IF(H16<=40,60+(H16-30)*3,60+30+(H16-40)*4)))) -> 0 | AC16: =IF(I16<20,0,IF(I16<25,20,IF(I16<30,40,IF(I16<=40,60+(I16-30)*3,60+30+(I16-40)*4)))) -> 0 | AD16: =IF(J16<20,0,IF(J16<25,20,IF(J16<30,40,IF(J16<=40,60+(J16-30)*3,60+30+(J16-40)*4)))) -> 0 | AE16: =IF(K16<20,0,IF(K16<25,20,IF(K16<30,40,IF(K16<=40,60+(K16-30)*3,60+30+(K16-40)*4)))) -> 0 | ... AL16: =IF(R16<20,0,IF(R16<25,20,IF(R16<30,40,IF(R16<=40,60+(R16-30)*3,60+30+(R16-40)*4)))) -> 0 | AM16: =SUM(X16:AL16) -> 200
A17: CA10766 | B17: ZAOUY MOHAMED | C17: MARAVILLA | S17: =SUM(D17:R17) -> 0 | T17: 1 | U17: CA10766 | V17: ZAOUY MOHAMED | W17: MARAVILLA | X17: =IF(D17<20,0,IF(D17<25,20,IF(D17<30,40,IF(D17<=40,60+(D17-30)*3,60+30+(D17-40)*4)))) -> 0 | Y17: =IF(E17<20,0,IF(E17<25,20,IF(E17<30,40,IF(E17<=40,60+(E17-30)*3,60+30+(E17-40)*4)))) -> 0 | Z17: =IF(F17<20,0,IF(F17<25,20,IF(F17<30,40,IF(F17<=40,60+(F17-30)*3,60+30+(F17-40)*4)))) -> 0 | AA17: =IF(G17<20,0,IF(G17<25,20,IF(G17<30,40,IF(G17<=40,60+(G17-30)*3,60+30+(G17-40)*4)))) -> 0 | AB17: =IF(H17<20,0,IF(H17<25,20,IF(H17<30,40,IF(H17<=40,60+(H17-30)*3,60+30+(H17-40)*4)))) -> 0 | AC17: =IF(I17<20,0,IF(I17<25,20,IF(I17<30,40,IF(I17<=40,60+(I17-30)*3,60+30+(I17-40)*4)))) -> 0 | AD17: =IF(J17<20,0,IF(J17<25,20,IF(J17<30,40,IF(J17<=40,60+(J17-30)*3,60+30+(J17-40)*4)))) -> 0 | AE17: =IF(K17<20,0,IF(K17<25,20,IF(K17<30,40,IF(K17<=40,60+(K17-30)*3,60+30+(K17-40)*4)))) -> 0 | ... AL17: =IF(R17<20,0,IF(R17<25,20,IF(R17<30,40,IF(R17<=40,60+(R17-30)*3,60+30+(R17-40)*4)))) -> 0 | AM17: =SUM(X17:AL17) -> 0
A18: CA10850 | B18: CHAFIK SOUAD | C18: MARAVILLA | F18: 7.5 | G18: 6 | H18: 6 | I18: 13.5 | J18: 16.5 | K18: 30 | M18: 36 | S18: =SUM(D18:R18) -> 115.5 | T18: 1 | U18: CA10850 | V18: CHAFIK SOUAD | W18: MARAVILLA | X18: =IF(D18<20,0,IF(D18<25,20,IF(D18<30,40,IF(D18<=40,60+(D18-30)*3,60+30+(D18-40)*4)))) -> 0 | Y18: =IF(E18<20,0,IF(E18<25,20,IF(E18<30,40,IF(E18<=40,60+(E18-30)*3,60+30+(E18-40)*4)))) -> 0 | Z18: =IF(F18<20,0,IF(F18<25,20,IF(F18<30,40,IF(F18<=40,60+(F18-30)*3,60+30+(F18-40)*4)))) -> 0 | AA18: =IF(G18<20,0,IF(G18<25,20,IF(G18<30,40,IF(G18<=40,60+(G18-30)*3,60+30+(G18-40)*4)))) -> 0 | AB18: =IF(H18<20,0,IF(H18<25,20,IF(H18<30,40,IF(H18<=40,60+(H18-30)*3,60+30+(H18-40)*4)))) -> 0 | AC18: =IF(I18<20,0,IF(I18<25,20,IF(I18<30,40,IF(I18<=40,60+(I18-30)*3,60+30+(I18-40)*4)))) -> 0 | AD18: =IF(J18<20,0,IF(J18<25,20,IF(J18<30,40,IF(J18<=40,60+(J18-30)*3,60+30+(J18-40)*4)))) -> 0 | AE18: =IF(K18<20,0,IF(K18<25,20,IF(K18<30,40,IF(K18<=40,60+(K18-30)*3,60+30+(K18-40)*4)))) -> 60 | ... AL18: =IF(R18<20,0,IF(R18<25,20,IF(R18<30,40,IF(R18<=40,60+(R18-30)*3,60+30+(R18-40)*4)))) -> 0 | AM18: =SUM(X18:AL18) -> 138
A19: CA10907 | B19: AARIOUA OUMAIMA | C19: MARAVILLA | L19: 48 | M19: 46.5 | S19: =SUM(D19:R19) -> 94.5 | T19: 1 | U19: CA10907 | V19: AARIOUA OUMAIMA | W19: MARAVILLA | X19: =IF(D19<20,0,IF(D19<25,20,IF(D19<30,40,IF(D19<=40,60+(D19-30)*3,60+30+(D19-40)*4)))) -> 0 | Y19: =IF(E19<20,0,IF(E19<25,20,IF(E19<30,40,IF(E19<=40,60+(E19-30)*3,60+30+(E19-40)*4)))) -> 0 | Z19: =IF(F19<20,0,IF(F19<25,20,IF(F19<30,40,IF(F19<=40,60+(F19-30)*3,60+30+(F19-40)*4)))) -> 0 | AA19: =IF(G19<20,0,IF(G19<25,20,IF(G19<30,40,IF(G19<=40,60+(G19-30)*3,60+30+(G19-40)*4)))) -> 0 | AB19: =IF(H19<20,0,IF(H19<25,20,IF(H19<30,40,IF(H19<=40,60+(H19-30)*3,60+30+(H19-40)*4)))) -> 0 | AC19: =IF(I19<20,0,IF(I19<25,20,IF(I19<30,40,IF(I19<=40,60+(I19-30)*3,60+30+(I19-40)*4)))) -> 0 | AD19: =IF(J19<20,0,IF(J19<25,20,IF(J19<30,40,IF(J19<=40,60+(J19-30)*3,60+30+(J19-40)*4)))) -> 0 | AE19: =IF(K19<20,0,IF(K19<25,20,IF(K19<30,40,IF(K19<=40,60+(K19-30)*3,60+30+(K19-40)*4)))) -> 0 | ... AL19: =IF(R19<20,0,IF(R19<25,20,IF(R19<30,40,IF(R19<=40,60+(R19-30)*3,60+30+(R19-40)*4)))) -> 0 | AM19: =SUM(X19:AL19) -> 238
A20: CC10049 | B20: KHADDI IBRAHIIM | C20: MARAVILLA | S20: =SUM(D20:R20) -> 0 | T20: 1 | U20: CC10049 | V20: KHADDI IBRAHIIM | W20: MARAVILLA | X20: =IF(D20<20,0,IF(D20<25,20,IF(D20<30,40,IF(D20<=40,60+(D20-30)*3,60+30+(D20-40)*4)))) -> 0 | Y20: =IF(E20<20,0,IF(E20<25,20,IF(E20<30,40,IF(E20<=40,60+(E20-30)*3,60+30+(E20-40)*4)))) -> 0 | Z20: =IF(F20<20,0,IF(F20<25,20,IF(F20<30,40,IF(F20<=40,60+(F20-30)*3,60+30+(F20-40)*4)))) -> 0 | AA20: =IF(G20<20,0,IF(G20<25,20,IF(G20<30,40,IF(G20<=40,60+(G20-30)*3,60+30+(G20-40)*4)))) -> 0 | AB20: =IF(H20<20,0,IF(H20<25,20,IF(H20<30,40,IF(H20<=40,60+(H20-30)*3,60+30+(H20-40)*4)))) -> 0 | AC20: =IF(I20<20,0,IF(I20<25,20,IF(I20<30,40,IF(I20<=40,60+(I20-30)*3,60+30+(I20-40)*4)))) -> 0 | AD20: =IF(J20<20,0,IF(J20<25,20,IF(J20<30,40,IF(J20<=40,60+(J20-30)*3,60+30+(J20-40)*4)))) -> 0 | AE20: =IF(K20<20,0,IF(K20<25,20,IF(K20<30,40,IF(K20<=40,60+(K20-30)*3,60+30+(K20-40)*4)))) -> 0 | ... AL20: =IF(R20<20,0,IF(R20<25,20,IF(R20<30,40,IF(R20<=40,60+(R20-30)*3,60+30+(R20-40)*4)))) -> 0 | AM20: =SUM(X20:AL20) -> 0
A21: CC10557 | B21: LARHRISSI BADR | C21: MARAVILLA | S21: =SUM(D21:R21) -> 0 | T21: 1 | U21: CC10557 | V21: LARHRISSI BADR | W21: MARAVILLA | X21: =IF(D21<20,0,IF(D21<25,20,IF(D21<30,40,IF(D21<=40,60+(D21-30)*3,60+30+(D21-40)*4)))) -> 0 | Y21: =IF(E21<20,0,IF(E21<25,20,IF(E21<30,40,IF(E21<=40,60+(E21-30)*3,60+30+(E21-40)*4)))) -> 0 | Z21: =IF(F21<20,0,IF(F21<25,20,IF(F21<30,40,IF(F21<=40,60+(F21-30)*3,60+30+(F21-40)*4)))) -> 0 | AA21: =IF(G21<20,0,IF(G21<25,20,IF(G21<30,40,IF(G21<=40,60+(G21-30)*3,60+30+(G21-40)*4)))) -> 0 | AB21: =IF(H21<20,0,IF(H21<25,20,IF(H21<30,40,IF(H21<=40,60+(H21-30)*3,60+30+(H21-40)*4)))) -> 0 | AC21: =IF(I21<20,0,IF(I21<25,20,IF(I21<30,40,IF(I21<=40,60+(I21-30)*3,60+30+(I21-40)*4)))) -> 0 | AD21: =IF(J21<20,0,IF(J21<25,20,IF(J21<30,40,IF(J21<=40,60+(J21-30)*3,60+30+(J21-40)*4)))) -> 0 | AE21: =IF(K21<20,0,IF(K21<25,20,IF(K21<30,40,IF(K21<=40,60+(K21-30)*3,60+30+(K21-40)*4)))) -> 0 | ... AL21: =IF(R21<20,0,IF(R21<25,20,IF(R21<30,40,IF(R21<=40,60+(R21-30)*3,60+30+(R21-40)*4)))) -> 0 | AM21: =SUM(X21:AL21) -> 0
A22: CC10839 | B22: EL HARBAOUI HASSAN | C22: MARAVILLA | I22: 3 | S22: =SUM(D22:R22) -> 3 | T22: 1 | U22: CC10839 | V22: EL HARBAOUI HASSAN | W22: MARAVILLA | X22: =IF(D22<20,0,IF(D22<25,20,IF(D22<30,40,IF(D22<=40,60+(D22-30)*3,60+30+(D22-40)*4)))) -> 0 | Y22: =IF(E22<20,0,IF(E22<25,20,IF(E22<30,40,IF(E22<=40,60+(E22-30)*3,60+30+(E22-40)*4)))) -> 0 | Z22: =IF(F22<20,0,IF(F22<25,20,IF(F22<30,40,IF(F22<=40,60+(F22-30)*3,60+30+(F22-40)*4)))) -> 0 | AA22: =IF(G22<20,0,IF(G22<25,20,IF(G22<30,40,IF(G22<=40,60+(G22-30)*3,60+30+(G22-40)*4)))) -> 0 | AB22: =IF(H22<20,0,IF(H22<25,20,IF(H22<30,40,IF(H22<=40,60+(H22-30)*3,60+30+(H22-40)*4)))) -> 0 | AC22: =IF(I22<20,0,IF(I22<25,20,IF(I22<30,40,IF(I22<=40,60+(I22-30)*3,60+30+(I22-40)*4)))) -> 0 | AD22: =IF(J22<20,0,IF(J22<25,20,IF(J22<30,40,IF(J22<=40,60+(J22-30)*3,60+30+(J22-40)*4)))) -> 0 | AE22: =IF(K22<20,0,IF(K22<25,20,IF(K22<30,40,IF(K22<=40,60+(K22-30)*3,60+30+(K22-40)*4)))) -> 0 | ... AL22: =IF(R22<20,0,IF(R22<25,20,IF(R22<30,40,IF(R22<=40,60+(R22-30)*3,60+30+(R22-40)*4)))) -> 0 | AM22: =SUM(X22:AL22) -> 0
A23: DD10113 | B23: BENZAINA HASSAN | C23: MARAVILLA | M23: 25.5 | S23: =SUM(D23:R23) -> 25.5 | T23: 1 | U23: DD10113 | V23: BENZAINA HASSAN | W23: MARAVILLA | X23: =IF(D23<20,0,IF(D23<25,20,IF(D23<30,40,IF(D23<=40,60+(D23-30)*3,60+30+(D23-40)*4)))) -> 0 | Y23: =IF(E23<20,0,IF(E23<25,20,IF(E23<30,40,IF(E23<=40,60+(E23-30)*3,60+30+(E23-40)*4)))) -> 0 | Z23: =IF(F23<20,0,IF(F23<25,20,IF(F23<30,40,IF(F23<=40,60+(F23-30)*3,60+30+(F23-40)*4)))) -> 0 | AA23: =IF(G23<20,0,IF(G23<25,20,IF(G23<30,40,IF(G23<=40,60+(G23-30)*3,60+30+(G23-40)*4)))) -> 0 | AB23: =IF(H23<20,0,IF(H23<25,20,IF(H23<30,40,IF(H23<=40,60+(H23-30)*3,60+30+(H23-40)*4)))) -> 0 | AC23: =IF(I23<20,0,IF(I23<25,20,IF(I23<30,40,IF(I23<=40,60+(I23-30)*3,60+30+(I23-40)*4)))) -> 0 | AD23: =IF(J23<20,0,IF(J23<25,20,IF(J23<30,40,IF(J23<=40,60+(J23-30)*3,60+30+(J23-40)*4)))) -> 0 | AE23: =IF(K23<20,0,IF(K23<25,20,IF(K23<30,40,IF(K23<=40,60+(K23-30)*3,60+30+(K23-40)*4)))) -> 0 | ... AL23: =IF(R23<20,0,IF(R23<25,20,IF(R23<30,40,IF(R23<=40,60+(R23-30)*3,60+30+(R23-40)*4)))) -> 0 | AM23: =SUM(X23:AL23) -> 40
A24: DD10115 | B24: MOUMAN ABDELGHANI | C24: MARAVILLA | M24: 15 | S24: =SUM(D24:R24) -> 15 | T24: 1 | U24: DD10115 | V24: MOUMAN ABDELGHANI | W24: MARAVILLA | X24: =IF(D24<20,0,IF(D24<25,20,IF(D24<30,40,IF(D24<=40,60+(D24-30)*3,60+30+(D24-40)*4)))) -> 0 | Y24: =IF(E24<20,0,IF(E24<25,20,IF(E24<30,40,IF(E24<=40,60+(E24-30)*3,60+30+(E24-40)*4)))) -> 0 | Z24: =IF(F24<20,0,IF(F24<25,20,IF(F24<30,40,IF(F24<=40,60+(F24-30)*3,60+30+(F24-40)*4)))) -> 0 | AA24: =IF(G24<20,0,IF(G24<25,20,IF(G24<30,40,IF(G24<=40,60+(G24-30)*3,60+30+(G24-40)*4)))) -> 0 | AB24: =IF(H24<20,0,IF(H24<25,20,IF(H24<30,40,IF(H24<=40,60+(H24-30)*3,60+30+(H24-40)*4)))) -> 0 | AC24: =IF(I24<20,0,IF(I24<25,20,IF(I24<30,40,IF(I24<=40,60+(I24-30)*3,60+30+(I24-40)*4)))) -> 0 | AD24: =IF(J24<20,0,IF(J24<25,20,IF(J24<30,40,IF(J24<=40,60+(J24-30)*3,60+30+(J24-40)*4)))) -> 0 | AE24: =IF(K24<20,0,IF(K24<25,20,IF(K24<30,40,IF(K24<=40,60+(K24-30)*3,60+30+(K24-40)*4)))) -> 0 | ... AL24: =IF(R24<20,0,IF(R24<25,20,IF(R24<30,40,IF(R24<=40,60+(R24-30)*3,60+30+(R24-40)*4)))) -> 0 | AM24: =SUM(X24:AL24) -> 0
A25: DD10245 | B25: ANNAICH MOHAMMED | C25: MARAVILLA | M25: 13.5 | S25: =SUM(D25:R25) -> 13.5 | T25: 1 | U25: DD10245 | V25: ANNAICH MOHAMMED | W25: MARAVILLA | X25: =IF(D25<20,0,IF(D25<25,20,IF(D25<30,40,IF(D25<=40,60+(D25-30)*3,60+30+(D25-40)*4)))) -> 0 | Y25: =IF(E25<20,0,IF(E25<25,20,IF(E25<30,40,IF(E25<=40,60+(E25-30)*3,60+30+(E25-40)*4)))) -> 0 | Z25: =IF(F25<20,0,IF(F25<25,20,IF(F25<30,40,IF(F25<=40,60+(F25-30)*3,60+30+(F25-40)*4)))) -> 0 | AA25: =IF(G25<20,0,IF(G25<25,20,IF(G25<30,40,IF(G25<=40,60+(G25-30)*3,60+30+(G25-40)*4)))) -> 0 | AB25: =IF(H25<20,0,IF(H25<25,20,IF(H25<30,40,IF(H25<=40,60+(H25-30)*3,60+30+(H25-40)*4)))) -> 0 | AC25: =IF(I25<20,0,IF(I25<25,20,IF(I25<30,40,IF(I25<=40,60+(I25-30)*3,60+30+(I25-40)*4)))) -> 0 | AD25: =IF(J25<20,0,IF(J25<25,20,IF(J25<30,40,IF(J25<=40,60+(J25-30)*3,60+30+(J25-40)*4)))) -> 0 | AE25: =IF(K25<20,0,IF(K25<25,20,IF(K25<30,40,IF(K25<=40,60+(K25-30)*3,60+30+(K25-40)*4)))) -> 0 | ... AL25: =IF(R25<20,0,IF(R25<25,20,IF(R25<30,40,IF(R25<=40,60+(R25-30)*3,60+30+(R25-40)*4)))) -> 0 | AM25: =SUM(X25:AL25) -> 0
A26: DD10439 | B26: KALLALI MOHAMED | C26: MARAVILLA | S26: =SUM(D26:R26) -> 0 | T26: 1 | U26: DD10439 | V26: KALLALI MOHAMED | W26: MARAVILLA | X26: =IF(D26<20,0,IF(D26<25,20,IF(D26<30,40,IF(D26<=40,60+(D26-30)*3,60+30+(D26-40)*4)))) -> 0 | Y26: =IF(E26<20,0,IF(E26<25,20,IF(E26<30,40,IF(E26<=40,60+(E26-30)*3,60+30+(E26-40)*4)))) -> 0 | Z26: =IF(F26<20,0,IF(F26<25,20,IF(F26<30,40,IF(F26<=40,60+(F26-30)*3,60+30+(F26-40)*4)))) -> 0 | AA26: =IF(G26<20,0,IF(G26<25,20,IF(G26<30,40,IF(G26<=40,60+(G26-30)*3,60+30+(G26-40)*4)))) -> 0 | AB26: =IF(H26<20,0,IF(H26<25,20,IF(H26<30,40,IF(H26<=40,60+(H26-30)*3,60+30+(H26-40)*4)))) -> 0 | AC26: =IF(I26<20,0,IF(I26<25,20,IF(I26<30,40,IF(I26<=40,60+(I26-30)*3,60+30+(I26-40)*4)))) -> 0 | AD26: =IF(J26<20,0,IF(J26<25,20,IF(J26<30,40,IF(J26<=40,60+(J26-30)*3,60+30+(J26-40)*4)))) -> 0 | AE26: =IF(K26<20,0,IF(K26<25,20,IF(K26<30,40,IF(K26<=40,60+(K26-30)*3,60+30+(K26-40)*4)))) -> 0 | ... AL26: =IF(R26<20,0,IF(R26<25,20,IF(R26<30,40,IF(R26<=40,60+(R26-30)*3,60+30+(R26-40)*4)))) -> 0 | AM26: =SUM(X26:AL26) -> 0
A27: DD10517 | B27: KALALI NOURDINNE | C27: MARAVILLA | S27: =SUM(D27:R27) -> 0 | T27: 1 | U27: DD10517 | V27: KALALI NOURDINNE | W27: MARAVILLA | X27: =IF(D27<20,0,IF(D27<25,20,IF(D27<30,40,IF(D27<=40,60+(D27-30)*3,60+30+(D27-40)*4)))) -> 0 | Y27: =IF(E27<20,0,IF(E27<25,20,IF(E27<30,40,IF(E27<=40,60+(E27-30)*3,60+30+(E27-40)*4)))) -> 0 | Z27: =IF(F27<20,0,IF(F27<25,20,IF(F27<30,40,IF(F27<=40,60+(F27-30)*3,60+30+(F27-40)*4)))) -> 0 | AA27: =IF(G27<20,0,IF(G27<25,20,IF(G27<30,40,IF(G27<=40,60+(G27-30)*3,60+30+(G27-40)*4)))) -> 0 | AB27: =IF(H27<20,0,IF(H27<25,20,IF(H27<30,40,IF(H27<=40,60+(H27-30)*3,60+30+(H27-40)*4)))) -> 0 | AC27: =IF(I27<20,0,IF(I27<25,20,IF(I27<30,40,IF(I27<=40,60+(I27-30)*3,60+30+(I27-40)*4)))) -> 0 | AD27: =IF(J27<20,0,IF(J27<25,20,IF(J27<30,40,IF(J27<=40,60+(J27-30)*3,60+30+(J27-40)*4)))) -> 0 | AE27: =IF(K27<20,0,IF(K27<25,20,IF(K27<30,40,IF(K27<=40,60+(K27-30)*3,60+30+(K27-40)*4)))) -> 0 | ... AL27: =IF(R27<20,0,IF(R27<25,20,IF(R27<30,40,IF(R27<=40,60+(R27-30)*3,60+30+(R27-40)*4)))) -> 0 | AM27: =SUM(X27:AL27) -> 0
A28: DD10518 | B28: EL BAZZA MOUHSSINE | C28: MARAVILLA | S28: =SUM(D28:R28) -> 0 | T28: 1 | U28: DD10518 | V28: EL BAZZA MOUHSSINE | W28: MARAVILLA | X28: =IF(D28<20,0,IF(D28<25,20,IF(D28<30,40,IF(D28<=40,60+(D28-30)*3,60+30+(D28-40)*4)))) -> 0 | Y28: =IF(E28<20,0,IF(E28<25,20,IF(E28<30,40,IF(E28<=40,60+(E28-30)*3,60+30+(E28-40)*4)))) -> 0 | Z28: =IF(F28<20,0,IF(F28<25,20,IF(F28<30,40,IF(F28<=40,60+(F28-30)*3,60+30+(F28-40)*4)))) -> 0 | AA28: =IF(G28<20,0,IF(G28<25,20,IF(G28<30,40,IF(G28<=40,60+(G28-30)*3,60+30+(G28-40)*4)))) -> 0 | AB28: =IF(H28<20,0,IF(H28<25,20,IF(H28<30,40,IF(H28<=40,60+(H28-30)*3,60+30+(H28-40)*4)))) -> 0 | AC28: =IF(I28<20,0,IF(I28<25,20,IF(I28<30,40,IF(I28<=40,60+(I28-30)*3,60+30+(I28-40)*4)))) -> 0 | AD28: =IF(J28<20,0,IF(J28<25,20,IF(J28<30,40,IF(J28<=40,60+(J28-30)*3,60+30+(J28-40)*4)))) -> 0 | AE28: =IF(K28<20,0,IF(K28<25,20,IF(K28<30,40,IF(K28<=40,60+(K28-30)*3,60+30+(K28-40)*4)))) -> 0 | ... AL28: =IF(R28<20,0,IF(R28<25,20,IF(R28<30,40,IF(R28<=40,60+(R28-30)*3,60+30+(R28-40)*4)))) -> 0 | AM28: =SUM(X28:AL28) -> 0
A29: DD10519 | B29: EL AYDI RACHID | C29: MARAVILLA | M29: 18 | S29: =SUM(D29:R29) -> 18 | T29: 1 | U29: DD10519 | V29: EL AYDI RACHID | W29: MARAVILLA | X29: =IF(D29<20,0,IF(D29<25,20,IF(D29<30,40,IF(D29<=40,60+(D29-30)*3,60+30+(D29-40)*4)))) -> 0 | Y29: =IF(E29<20,0,IF(E29<25,20,IF(E29<30,40,IF(E29<=40,60+(E29-30)*3,60+30+(E29-40)*4)))) -> 0 | Z29: =IF(F29<20,0,IF(F29<25,20,IF(F29<30,40,IF(F29<=40,60+(F29-30)*3,60+30+(F29-40)*4)))) -> 0 | AA29: =IF(G29<20,0,IF(G29<25,20,IF(G29<30,40,IF(G29<=40,60+(G29-30)*3,60+30+(G29-40)*4)))) -> 0 | AB29: =IF(H29<20,0,IF(H29<25,20,IF(H29<30,40,IF(H29<=40,60+(H29-30)*3,60+30+(H29-40)*4)))) -> 0 | AC29: =IF(I29<20,0,IF(I29<25,20,IF(I29<30,40,IF(I29<=40,60+(I29-30)*3,60+30+(I29-40)*4)))) -> 0 | AD29: =IF(J29<20,0,IF(J29<25,20,IF(J29<30,40,IF(J29<=40,60+(J29-30)*3,60+30+(J29-40)*4)))) -> 0 | AE29: =IF(K29<20,0,IF(K29<25,20,IF(K29<30,40,IF(K29<=40,60+(K29-30)*3,60+30+(K29-40)*4)))) -> 0 | ... AL29: =IF(R29<20,0,IF(R29<25,20,IF(R29<30,40,IF(R29<=40,60+(R29-30)*3,60+30+(R29-40)*4)))) -> 0 | AM29: =SUM(X29:AL29) -> 0
A30: DD10524 | B30: ZAABOUL MOHAMED | C30: MARAVILLA | M30: 25.5 | S30: =SUM(D30:R30) -> 25.5 | T30: 1 | U30: DD10524 | V30: ZAABOUL MOHAMED | W30: MARAVILLA | X30: =IF(D30<20,0,IF(D30<25,20,IF(D30<30,40,IF(D30<=40,60+(D30-30)*3,60+30+(D30-40)*4)))) -> 0 | Y30: =IF(E30<20,0,IF(E30<25,20,IF(E30<30,40,IF(E30<=40,60+(E30-30)*3,60+30+(E30-40)*4)))) -> 0 | Z30: =IF(F30<20,0,IF(F30<25,20,IF(F30<30,40,IF(F30<=40,60+(F30-30)*3,60+30+(F30-40)*4)))) -> 0 | AA30: =IF(G30<20,0,IF(G30<25,20,IF(G30<30,40,IF(G30<=40,60+(G30-30)*3,60+30+(G30-40)*4)))) -> 0 | AB30: =IF(H30<20,0,IF(H30<25,20,IF(H30<30,40,IF(H30<=40,60+(H30-30)*3,60+30+(H30-40)*4)))) -> 0 | AC30: =IF(I30<20,0,IF(I30<25,20,IF(I30<30,40,IF(I30<=40,60+(I30-30)*3,60+30+(I30-40)*4)))) -> 0 | AD30: =IF(J30<20,0,IF(J30<25,20,IF(J30<30,40,IF(J30<=40,60+(J30-30)*3,60+30+(J30-40)*4)))) -> 0 | AE30: =IF(K30<20,0,IF(K30<25,20,IF(K30<30,40,IF(K30<=40,60+(K30-30)*3,60+30+(K30-40)*4)))) -> 0 | ... AL30: =IF(R30<20,0,IF(R30<25,20,IF(R30<30,40,IF(R30<=40,60+(R30-30)*3,60+30+(R30-40)*4)))) -> 0 | AM30: =SUM(X30:AL30) -> 40
A31: DD10548 | B31: BENHLAL ABDERRAHMAN | C31: MARAVILLA | S31: =SUM(D31:R31) -> 0 | T31: 1 | U31: DD10548 | V31: BENHLAL ABDERRAHMAN | W31: MARAVILLA | X31: =IF(D31<20,0,IF(D31<25,20,IF(D31<30,40,IF(D31<=40,60+(D31-30)*3,60+30+(D31-40)*4)))) -> 0 | Y31: =IF(E31<20,0,IF(E31<25,20,IF(E31<30,40,IF(E31<=40,60+(E31-30)*3,60+30+(E31-40)*4)))) -> 0 | Z31: =IF(F31<20,0,IF(F31<25,20,IF(F31<30,40,IF(F31<=40,60+(F31-30)*3,60+30+(F31-40)*4)))) -> 0 | AA31: =IF(G31<20,0,IF(G31<25,20,IF(G31<30,40,IF(G31<=40,60+(G31-30)*3,60+30+(G31-40)*4)))) -> 0 | AB31: =IF(H31<20,0,IF(H31<25,20,IF(H31<30,40,IF(H31<=40,60+(H31-30)*3,60+30+(H31-40)*4)))) -> 0 | AC31: =IF(I31<20,0,IF(I31<25,20,IF(I31<30,40,IF(I31<=40,60+(I31-30)*3,60+30+(I31-40)*4)))) -> 0 | AD31: =IF(J31<20,0,IF(J31<25,20,IF(J31<30,40,IF(J31<=40,60+(J31-30)*3,60+30+(J31-40)*4)))) -> 0 | AE31: =IF(K31<20,0,IF(K31<25,20,IF(K31<30,40,IF(K31<=40,60+(K31-30)*3,60+30+(K31-40)*4)))) -> 0 | ... AL31: =IF(R31<20,0,IF(R31<25,20,IF(R31<30,40,IF(R31<=40,60+(R31-30)*3,60+30+(R31-40)*4)))) -> 0 | AM31: =SUM(X31:AL31) -> 0
A32: DD10550 | B32: EL AYDI ABDELTIF | C32: MARAVILLA | M32: 16.5 | S32: =SUM(D32:R32) -> 16.5 | T32: 1 | U32: DD10550 | V32: EL AYDI ABDELTIF | W32: MARAVILLA | X32: =IF(D32<20,0,IF(D32<25,20,IF(D32<30,40,IF(D32<=40,60+(D32-30)*3,60+30+(D32-40)*4)))) -> 0 | Y32: =IF(E32<20,0,IF(E32<25,20,IF(E32<30,40,IF(E32<=40,60+(E32-30)*3,60+30+(E32-40)*4)))) -> 0 | Z32: =IF(F32<20,0,IF(F32<25,20,IF(F32<30,40,IF(F32<=40,60+(F32-30)*3,60+30+(F32-40)*4)))) -> 0 | AA32: =IF(G32<20,0,IF(G32<25,20,IF(G32<30,40,IF(G32<=40,60+(G32-30)*3,60+30+(G32-40)*4)))) -> 0 | AB32: =IF(H32<20,0,IF(H32<25,20,IF(H32<30,40,IF(H32<=40,60+(H32-30)*3,60+30+(H32-40)*4)))) -> 0 | AC32: =IF(I32<20,0,IF(I32<25,20,IF(I32<30,40,IF(I32<=40,60+(I32-30)*3,60+30+(I32-40)*4)))) -> 0 | AD32: =IF(J32<20,0,IF(J32<25,20,IF(J32<30,40,IF(J32<=40,60+(J32-30)*3,60+30+(J32-40)*4)))) -> 0 | AE32: =IF(K32<20,0,IF(K32<25,20,IF(K32<30,40,IF(K32<=40,60+(K32-30)*3,60+30+(K32-40)*4)))) -> 0 | ... AL32: =IF(R32<20,0,IF(R32<25,20,IF(R32<30,40,IF(R32<=40,60+(R32-30)*3,60+30+(R32-40)*4)))) -> 0 | AM32: =SUM(X32:AL32) -> 0
A33: DD10574 | B33: BELHAID M'BAREK | C33: MARAVILLA | M33: 13.5 | S33: =SUM(D33:R33) -> 13.5 | T33: 1 | U33: DD10574 | V33: BELHAID M'BAREK | W33: MARAVILLA | X33: =IF(D33<20,0,IF(D33<25,20,IF(D33<30,40,IF(D33<=40,60+(D33-30)*3,60+30+(D33-40)*4)))) -> 0 | Y33: =IF(E33<20,0,IF(E33<25,20,IF(E33<30,40,IF(E33<=40,60+(E33-30)*3,60+30+(E33-40)*4)))) -> 0 | Z33: =IF(F33<20,0,IF(F33<25,20,IF(F33<30,40,IF(F33<=40,60+(F33-30)*3,60+30+(F33-40)*4)))) -> 0 | AA33: =IF(G33<20,0,IF(G33<25,20,IF(G33<30,40,IF(G33<=40,60+(G33-30)*3,60+30+(G33-40)*4)))) -> 0 | AB33: =IF(H33<20,0,IF(H33<25,20,IF(H33<30,40,IF(H33<=40,60+(H33-30)*3,60+30+(H33-40)*4)))) -> 0 | AC33: =IF(I33<20,0,IF(I33<25,20,IF(I33<30,40,IF(I33<=40,60+(I33-30)*3,60+30+(I33-40)*4)))) -> 0 | AD33: =IF(J33<20,0,IF(J33<25,20,IF(J33<30,40,IF(J33<=40,60+(J33-30)*3,60+30+(J33-40)*4)))) -> 0 | AE33: =IF(K33<20,0,IF(K33<25,20,IF(K33<30,40,IF(K33<=40,60+(K33-30)*3,60+30+(K33-40)*4)))) -> 0 | ... AL33: =IF(R33<20,0,IF(R33<25,20,IF(R33<30,40,IF(R33<=40,60+(R33-30)*3,60+30+(R33-40)*4)))) -> 0 | AM33: =SUM(X33:AL33) -> 0
A34: DD10575 | B34: KALALI 2 AHMED | C34: MARAVILLA | M34: 16.5 | S34: =SUM(D34:R34) -> 16.5 | T34: 1 | U34: DD10575 | V34: KALALI 2 AHMED | W34: MARAVILLA | X34: =IF(D34<20,0,IF(D34<25,20,IF(D34<30,40,IF(D34<=40,60+(D34-30)*3,60+30+(D34-40)*4)))) -> 0 | Y34: =IF(E34<20,0,IF(E34<25,20,IF(E34<30,40,IF(E34<=40,60+(E34-30)*3,60+30+(E34-40)*4)))) -> 0 | Z34: =IF(F34<20,0,IF(F34<25,20,IF(F34<30,40,IF(F34<=40,60+(F34-30)*3,60+30+(F34-40)*4)))) -> 0 | AA34: =IF(G34<20,0,IF(G34<25,20,IF(G34<30,40,IF(G34<=40,60+(G34-30)*3,60+30+(G34-40)*4)))) -> 0 | AB34: =IF(H34<20,0,IF(H34<25,20,IF(H34<30,40,IF(H34<=40,60+(H34-30)*3,60+30+(H34-40)*4)))) -> 0 | AC34: =IF(I34<20,0,IF(I34<25,20,IF(I34<30,40,IF(I34<=40,60+(I34-30)*3,60+30+(I34-40)*4)))) -> 0 | AD34: =IF(J34<20,0,IF(J34<25,20,IF(J34<30,40,IF(J34<=40,60+(J34-30)*3,60+30+(J34-40)*4)))) -> 0 | AE34: =IF(K34<20,0,IF(K34<25,20,IF(K34<30,40,IF(K34<=40,60+(K34-30)*3,60+30+(K34-40)*4)))) -> 0 | ... AL34: =IF(R34<20,0,IF(R34<25,20,IF(R34<30,40,IF(R34<=40,60+(R34-30)*3,60+30+(R34-40)*4)))) -> 0 | AM34: =SUM(X34:AL34) -> 0
A35: DD10593 | B35: EL HAITAM MOHAMED | C35: MARAVILLA | S35: =SUM(D35:R35) -> 0 | T35: 1 | U35: DD10593 | V35: EL HAITAM MOHAMED | W35: MARAVILLA | X35: =IF(D35<20,0,IF(D35<25,20,IF(D35<30,40,IF(D35<=40,60+(D35-30)*3,60+30+(D35-40)*4)))) -> 0 | Y35: =IF(E35<20,0,IF(E35<25,20,IF(E35<30,40,IF(E35<=40,60+(E35-30)*3,60+30+(E35-40)*4)))) -> 0 | Z35: =IF(F35<20,0,IF(F35<25,20,IF(F35<30,40,IF(F35<=40,60+(F35-30)*3,60+30+(F35-40)*4)))) -> 0 | AA35: =IF(G35<20,0,IF(G35<25,20,IF(G35<30,40,IF(G35<=40,60+(G35-30)*3,60+30+(G35-40)*4)))) -> 0 | AB35: =IF(H35<20,0,IF(H35<25,20,IF(H35<30,40,IF(H35<=40,60+(H35-30)*3,60+30+(H35-40)*4)))) -> 0 | AC35: =IF(I35<20,0,IF(I35<25,20,IF(I35<30,40,IF(I35<=40,60+(I35-30)*3,60+30+(I35-40)*4)))) -> 0 | AD35: =IF(J35<20,0,IF(J35<25,20,IF(J35<30,40,IF(J35<=40,60+(J35-30)*3,60+30+(J35-40)*4)))) -> 0 | AE35: =IF(K35<20,0,IF(K35<25,20,IF(K35<30,40,IF(K35<=40,60+(K35-30)*3,60+30+(K35-40)*4)))) -> 0 | ... AL35: =IF(R35<20,0,IF(R35<25,20,IF(R35<30,40,IF(R35<=40,60+(R35-30)*3,60+30+(R35-40)*4)))) -> 0 | AM35: =SUM(X35:AL35) -> 0
A36: DD10594 | B36: TRIBACH ABDESLAM | C36: MARAVILLA | S36: =SUM(D36:R36) -> 0 | T36: 1 | U36: DD10594 | V36: TRIBACH ABDESLAM | W36: MARAVILLA | X36: =IF(D36<20,0,IF(D36<25,20,IF(D36<30,40,IF(D36<=40,60+(D36-30)*3,60+30+(D36-40)*4)))) -> 0 | Y36: =IF(E36<20,0,IF(E36<25,20,IF(E36<30,40,IF(E36<=40,60+(E36-30)*3,60+30+(E36-40)*4)))) -> 0 | Z36: =IF(F36<20,0,IF(F36<25,20,IF(F36<30,40,IF(F36<=40,60+(F36-30)*3,60+30+(F36-40)*4)))) -> 0 | AA36: =IF(G36<20,0,IF(G36<25,20,IF(G36<30,40,IF(G36<=40,60+(G36-30)*3,60+30+(G36-40)*4)))) -> 0 | AB36: =IF(H36<20,0,IF(H36<25,20,IF(H36<30,40,IF(H36<=40,60+(H36-30)*3,60+30+(H36-40)*4)))) -> 0 | AC36: =IF(I36<20,0,IF(I36<25,20,IF(I36<30,40,IF(I36<=40,60+(I36-30)*3,60+30+(I36-40)*4)))) -> 0 | AD36: =IF(J36<20,0,IF(J36<25,20,IF(J36<30,40,IF(J36<=40,60+(J36-30)*3,60+30+(J36-40)*4)))) -> 0 | AE36: =IF(K36<20,0,IF(K36<25,20,IF(K36<30,40,IF(K36<=40,60+(K36-30)*3,60+30+(K36-40)*4)))) -> 0 | ... AL36: =IF(R36<20,0,IF(R36<25,20,IF(R36<30,40,IF(R36<=40,60+(R36-30)*3,60+30+(R36-40)*4)))) -> 0 | AM36: =SUM(X36:AL36) -> 0
A37: DD10598 | B37: ROUICHAK IMAD | C37: MARAVILLA | S37: =SUM(D37:R37) -> 0 | T37: 1 | U37: DD10598 | V37: ROUICHAK IMAD | W37: MARAVILLA | X37: =IF(D37<20,0,IF(D37<25,20,IF(D37<30,40,IF(D37<=40,60+(D37-30)*3,60+30+(D37-40)*4)))) -> 0 | Y37: =IF(E37<20,0,IF(E37<25,20,IF(E37<30,40,IF(E37<=40,60+(E37-30)*3,60+30+(E37-40)*4)))) -> 0 | Z37: =IF(F37<20,0,IF(F37<25,20,IF(F37<30,40,IF(F37<=40,60+(F37-30)*3,60+30+(F37-40)*4)))) -> 0 | AA37: =IF(G37<20,0,IF(G37<25,20,IF(G37<30,40,IF(G37<=40,60+(G37-30)*3,60+30+(G37-40)*4)))) -> 0 | AB37: =IF(H37<20,0,IF(H37<25,20,IF(H37<30,40,IF(H37<=40,60+(H37-30)*3,60+30+(H37-40)*4)))) -> 0 | AC37: =IF(I37<20,0,IF(I37<25,20,IF(I37<30,40,IF(I37<=40,60+(I37-30)*3,60+30+(I37-40)*4)))) -> 0 | AD37: =IF(J37<20,0,IF(J37<25,20,IF(J37<30,40,IF(J37<=40,60+(J37-30)*3,60+30+(J37-40)*4)))) -> 0 | AE37: =IF(K37<20,0,IF(K37<25,20,IF(K37<30,40,IF(K37<=40,60+(K37-30)*3,60+30+(K37-40)*4)))) -> 0 | ... AL37: =IF(R37<20,0,IF(R37<25,20,IF(R37<30,40,IF(R37<=40,60+(R37-30)*3,60+30+(R37-40)*4)))) -> 0 | AM37: =SUM(X37:AL37) -> 0
A38: DD10599 | B38: KARDOUDA RACHID | C38: MARAVILLA | S38: =SUM(D38:R38) -> 0 | T38: 1 | U38: DD10599 | V38: KARDOUDA RACHID | W38: MARAVILLA | X38: =IF(D38<20,0,IF(D38<25,20,IF(D38<30,40,IF(D38<=40,60+(D38-30)*3,60+30+(D38-40)*4)))) -> 0 | Y38: =IF(E38<20,0,IF(E38<25,20,IF(E38<30,40,IF(E38<=40,60+(E38-30)*3,60+30+(E38-40)*4)))) -> 0 | Z38: =IF(F38<20,0,IF(F38<25,20,IF(F38<30,40,IF(F38<=40,60+(F38-30)*3,60+30+(F38-40)*4)))) -> 0 | AA38: =IF(G38<20,0,IF(G38<25,20,IF(G38<30,40,IF(G38<=40,60+(G38-30)*3,60+30+(G38-40)*4)))) -> 0 | AB38: =IF(H38<20,0,IF(H38<25,20,IF(H38<30,40,IF(H38<=40,60+(H38-30)*3,60+30+(H38-40)*4)))) -> 0 | AC38: =IF(I38<20,0,IF(I38<25,20,IF(I38<30,40,IF(I38<=40,60+(I38-30)*3,60+30+(I38-40)*4)))) -> 0 | AD38: =IF(J38<20,0,IF(J38<25,20,IF(J38<30,40,IF(J38<=40,60+(J38-30)*3,60+30+(J38-40)*4)))) -> 0 | AE38: =IF(K38<20,0,IF(K38<25,20,IF(K38<30,40,IF(K38<=40,60+(K38-30)*3,60+30+(K38-40)*4)))) -> 0 | ... AL38: =IF(R38<20,0,IF(R38<25,20,IF(R38<30,40,IF(R38<=40,60+(R38-30)*3,60+30+(R38-40)*4)))) -> 0 | AM38: =SUM(X38:AL38) -> 0
A39: DD10602 | B39: KALALI AHMED | C39: MARAVILLA | S39: =SUM(D39:R39) -> 0 | T39: 1 | U39: DD10602 | V39: KALALI AHMED | W39: MARAVILLA | X39: =IF(D39<20,0,IF(D39<25,20,IF(D39<30,40,IF(D39<=40,60+(D39-30)*3,60+30+(D39-40)*4)))) -> 0 | Y39: =IF(E39<20,0,IF(E39<25,20,IF(E39<30,40,IF(E39<=40,60+(E39-30)*3,60+30+(E39-40)*4)))) -> 0 | Z39: =IF(F39<20,0,IF(F39<25,20,IF(F39<30,40,IF(F39<=40,60+(F39-30)*3,60+30+(F39-40)*4)))) -> 0 | AA39: =IF(G39<20,0,IF(G39<25,20,IF(G39<30,40,IF(G39<=40,60+(G39-30)*3,60+30+(G39-40)*4)))) -> 0 | AB39: =IF(H39<20,0,IF(H39<25,20,IF(H39<30,40,IF(H39<=40,60+(H39-30)*3,60+30+(H39-40)*4)))) -> 0 | AC39: =IF(I39<20,0,IF(I39<25,20,IF(I39<30,40,IF(I39<=40,60+(I39-30)*3,60+30+(I39-40)*4)))) -> 0 | AD39: =IF(J39<20,0,IF(J39<25,20,IF(J39<30,40,IF(J39<=40,60+(J39-30)*3,60+30+(J39-40)*4)))) -> 0 | AE39: =IF(K39<20,0,IF(K39<25,20,IF(K39<30,40,IF(K39<=40,60+(K39-30)*3,60+30+(K39-40)*4)))) -> 0 | ... AL39: =IF(R39<20,0,IF(R39<25,20,IF(R39<30,40,IF(R39<=40,60+(R39-30)*3,60+30+(R39-40)*4)))) -> 0 | AM39: =SUM(X39:AL39) -> 0
A40: DD10645 | B40: TRIBACH OMAR | C40: MARAVILLA | S40: =SUM(D40:R40) -> 0 | T40: 1 | U40: DD10645 | V40: TRIBACH OMAR | W40: MARAVILLA | X40: =IF(D40<20,0,IF(D40<25,20,IF(D40<30,40,IF(D40<=40,60+(D40-30)*3,60+30+(D40-40)*4)))) -> 0 | Y40: =IF(E40<20,0,IF(E40<25,20,IF(E40<30,40,IF(E40<=40,60+(E40-30)*3,60+30+(E40-40)*4)))) -> 0 | Z40: =IF(F40<20,0,IF(F40<25,20,IF(F40<30,40,IF(F40<=40,60+(F40-30)*3,60+30+(F40-40)*4)))) -> 0 | AA40: =IF(G40<20,0,IF(G40<25,20,IF(G40<30,40,IF(G40<=40,60+(G40-30)*3,60+30+(G40-40)*4)))) -> 0 | AB40: =IF(H40<20,0,IF(H40<25,20,IF(H40<30,40,IF(H40<=40,60+(H40-30)*3,60+30+(H40-40)*4)))) -> 0 | AC40: =IF(I40<20,0,IF(I40<25,20,IF(I40<30,40,IF(I40<=40,60+(I40-30)*3,60+30+(I40-40)*4)))) -> 0 | AD40: =IF(J40<20,0,IF(J40<25,20,IF(J40<30,40,IF(J40<=40,60+(J40-30)*3,60+30+(J40-40)*4)))) -> 0 | AE40: =IF(K40<20,0,IF(K40<25,20,IF(K40<30,40,IF(K40<=40,60+(K40-30)*3,60+30+(K40-40)*4)))) -> 0 | ... AL40: =IF(R40<20,0,IF(R40<25,20,IF(R40<30,40,IF(R40<=40,60+(R40-30)*3,60+30+(R40-40)*4)))) -> 0 | AM40: =SUM(X40:AL40) -> 0
...

Sheet F1
A1: Matricule | B1: Personnel | C1: Variété | D1: 16 | E1: 17 | F1: 18 | G1: 19 | H1: 20 | I1: 21 | J1: 22 | K1: 23 | L1: 24 | M1: 25 | N1: 26 | O1: 27 | P1: 28 | Q1: 29 | R1: 30 | S1: Total | U1: Matricule | V1: Personnel | W1: Variété | X1: 16 | Y1: 17 | Z1: 18 | AA1: 19 | AB1: 20 | AC1: 21 | AD1: 22 | AE1: 23 | AF1: 24 | AG1: 25 | AH1: 26 | AI1: 27 | AJ1: 28 | AK1: 29 | AL1: 30 | AM1: Total
A2: AQ10810 | B2: AYADI FATIHA | C2: MARAVILLA | S2: =SUM(D2:R2) -> 0 | T2: 1 | U2: AQ10810 | V2: AYADI FATIHA | W2: MARAVILLA | X2: =IF(D2<20,0,IF(D2<25,20,IF(D2<30,40,IF(D2<=40,60+(D2-30)*3,60+30+(D2-40)*4)))) -> 0 | Y2: =IF(E2<20,0,IF(E2<25,20,IF(E2<30,40,IF(E2<=40,60+(E2-30)*3,60+30+(E2-40)*4)))) -> 0 | Z2: =IF(F2<20,0,IF(F2<25,20,IF(F2<30,40,IF(F2<=40,60+(F2-30)*3,60+30+(F2-40)*4)))) -> 0 | AA2: =IF(G2<20,0,IF(G2<25,20,IF(G2<30,40,IF(G2<=40,60+(G2-30)*3,60+30+(G2-40)*4)))) -> 0 | AB2: =IF(H2<20,0,IF(H2<25,20,IF(H2<30,40,IF(H2<=40,60+(H2-30)*3,60+30+(H2-40)*4)))) -> 0 | AC2: =IF(I2<20,0,IF(I2<25,20,IF(I2<30,40,IF(I2<=40,60+(I2-30)*3,60+30+(I2-40)*4)))) -> 0 | AD2: =IF(J2<20,0,IF(J2<25,20,IF(J2<30,40,IF(J2<=40,60+(J2-30)*3,60+30+(J2-40)*4)))) -> 0 | AE2: =IF(K2<20,0,IF(K2<25,20,IF(K2<30,40,IF(K2<=40,60+(K2-30)*3,60+30+(K2-40)*4)))) -> 0 | ... AL2: =IF(R2<20,0,IF(R2<25,20,IF(R2<30,40,IF(R2<=40,60+(R2-30)*3,60+30+(R2-40)*4)))) -> 0 | AM2: =SUM(X2:AL2) -> 0
A3: AQ10811 | B3: HOUSNIYA EL KHELIFA | C3: MARAVILLA | S3: =SUM(D3:R3) -> 0 | T3: 1 | U3: AQ10811 | V3: HOUSNIYA EL KHELIFA | W3: MARAVILLA | X3: =IF(D3<20,0,IF(D3<25,20,IF(D3<30,40,IF(D3<=40,60+(D3-30)*3,60+30+(D3-40)*4)))) -> 0 | Y3: =IF(E3<20,0,IF(E3<25,20,IF(E3<30,40,IF(E3<=40,60+(E3-30)*3,60+30+(E3-40)*4)))) -> 0 | Z3: =IF(F3<20,0,IF(F3<25,20,IF(F3<30,40,IF(F3<=40,60+(F3-30)*3,60+30+(F3-40)*4)))) -> 0 | AA3: =IF(G3<20,0,IF(G3<25,20,IF(G3<30,40,IF(G3<=40,60+(G3-30)*3,60+30+(G3-40)*4)))) -> 0 | AB3: =IF(H3<20,0,IF(H3<25,20,IF(H3<30,40,IF(H3<=40,60+(H3-30)*3,60+30+(H3-40)*4)))) -> 0 | AC3: =IF(I3<20,0,IF(I3<25,20,IF(I3<30,40,IF(I3<=40,60+(I3-30)*3,60+30+(I3-40)*4)))) -> 0 | AD3: =IF(J3<20,0,IF(J3<25,20,IF(J3<30,40,IF(J3<=40,60+(J3-30)*3,60+30+(J3-40)*4)))) -> 0 | AE3: =IF(K3<20,0,IF(K3<25,20,IF(K3<30,40,IF(K3<=40,60+(K3-30)*3,60+30+(K3-40)*4)))) -> 0 | ... AL3: =IF(R3<20,0,IF(R3<25,20,IF(R3<30,40,IF(R3<=40,60+(R3-30)*3,60+30+(R3-40)*4)))) -> 0 | AM3: =SUM(X3:AL3) -> 0
A4: AQ10812 | B4: EL CHAMSI ZOUHRA | C4: MARAVILLA | S4: =SUM(D4:R4) -> 0 | T4: 1 | U4: AQ10812 | V4: EL CHAMSI ZOUHRA | W4: MARAVILLA | X4: =IF(D4<20,0,IF(D4<25,20,IF(D4<30,40,IF(D4<=40,60+(D4-30)*3,60+30+(D4-40)*4)))) -> 0 | Y4: =IF(E4<20,0,IF(E4<25,20,IF(E4<30,40,IF(E4<=40,60+(E4-30)*3,60+30+(E4-40)*4)))) -> 0 | Z4: =IF(F4<20,0,IF(F4<25,20,IF(F4<30,40,IF(F4<=40,60+(F4-30)*3,60+30+(F4-40)*4)))) -> 0 | AA4: =IF(G4<20,0,IF(G4<25,20,IF(G4<30,40,IF(G4<=40,60+(G4-30)*3,60+30+(G4-40)*4)))) -> 0 | AB4: =IF(H4<20,0,IF(H4<25,20,IF(H4<30,40,IF(H4<=40,60+(H4-30)*3,60+30+(H4-40)*4)))) -> 0 | AC4: =IF(I4<20,0,IF(I4<25,20,IF(I4<30,40,IF(I4<=40,60+(I4-30)*3,60+30+(I4-40)*4)))) -> 0 | AD4: =IF(J4<20,0,IF(J4<25,20,IF(J4<30,40,IF(J4<=40,60+(J4-30)*3,60+30+(J4-40)*4)))) -> 0 | AE4: =IF(K4<20,0,IF(K4<25,20,IF(K4<30,40,IF(K4<=40,60+(K4-30)*3,60+30+(K4-40)*4)))) -> 0 | ... AL4: =IF(R4<20,0,IF(R4<25,20,IF(R4<30,40,IF(R4<=40,60+(R4-30)*3,60+30+(R4-40)*4)))) -> 0 | AM4: =SUM(X4:AL4) -> 0
A5: AQ10813 | B5: EL JAMAL KHAADIJA | C5: MARAVILLA | S5: =SUM(D5:R5) -> 0 | T5: 1 | U5: AQ10813 | V5: EL JAMAL KHAADIJA | W5: MARAVILLA | X5: =IF(D5<20,0,IF(D5<25,20,IF(D5<30,40,IF(D5<=40,60+(D5-30)*3,60+30+(D5-40)*4)))) -> 0 | Y5: =IF(E5<20,0,IF(E5<25,20,IF(E5<30,40,IF(E5<=40,60+(E5-30)*3,60+30+(E5-40)*4)))) -> 0 | Z5: =IF(F5<20,0,IF(F5<25,20,IF(F5<30,40,IF(F5<=40,60+(F5-30)*3,60+30+(F5-40)*4)))) -> 0 | AA5: =IF(G5<20,0,IF(G5<25,20,IF(G5<30,40,IF(G5<=40,60+(G5-30)*3,60+30+(G5-40)*4)))) -> 0 | AB5: =IF(H5<20,0,IF(H5<25,20,IF(H5<30,40,IF(H5<=40,60+(H5-30)*3,60+30+(H5-40)*4)))) -> 0 | AC5: =IF(I5<20,0,IF(I5<25,20,IF(I5<30,40,IF(I5<=40,60+(I5-30)*3,60+30+(I5-40)*4)))) -> 0 | AD5: =IF(J5<20,0,IF(J5<25,20,IF(J5<30,40,IF(J5<=40,60+(J5-30)*3,60+30+(J5-40)*4)))) -> 0 | AE5: =IF(K5<20,0,IF(K5<25,20,IF(K5<30,40,IF(K5<=40,60+(K5-30)*3,60+30+(K5-40)*4)))) -> 0 | ... AL5: =IF(R5<20,0,IF(R5<25,20,IF(R5<30,40,IF(R5<=40,60+(R5-30)*3,60+30+(R5-40)*4)))) -> 0 | AM5: =SUM(X5:AL5) -> 0
A6: AQ10814 | B6: EL ZAIME FATIMA ZOHRA | C6: MARAVILLA | S6: =SUM(D6:R6) -> 0 | T6: 1 | U6: AQ10814 | V6: EL ZAIME FATIMA ZOHRA | W6: MARAVILLA | X6: =IF(D6<20,0,IF(D6<25,20,IF(D6<30,40,IF(D6<=40,60+(D6-30)*3,60+30+(D6-40)*4)))) -> 0 | Y6: =IF(E6<20,0,IF(E6<25,20,IF(E6<30,40,IF(E6<=40,60+(E6-30)*3,60+30+(E6-40)*4)))) -> 0 | Z6: =IF(F6<20,0,IF(F6<25,20,IF(F6<30,40,IF(F6<=40,60+(F6-30)*3,60+30+(F6-40)*4)))) -> 0 | AA6: =IF(G6<20,0,IF(G6<25,20,IF(G6<30,40,IF(G6<=40,60+(G6-30)*3,60+30+(G6-40)*4)))) -> 0 | AB6: =IF(H6<20,0,IF(H6<25,20,IF(H6<30,40,IF(H6<=40,60+(H6-30)*3,60+30+(H6-40)*4)))) -> 0 | AC6: =IF(I6<20,0,IF(I6<25,20,IF(I6<30,40,IF(I6<=40,60+(I6-30)*3,60+30+(I6-40)*4)))) -> 0 | AD6: =IF(J6<20,0,IF(J6<25,20,IF(J6<30,40,IF(J6<=40,60+(J6-30)*3,60+30+(J6-40)*4)))) -> 0 | AE6: =IF(K6<20,0,IF(K6<25,20,IF(K6<30,40,IF(K6<=40,60+(K6-30)*3,60+30+(K6-40)*4)))) -> 0 | ... AL6: =IF(R6<20,0,IF(R6<25,20,IF(R6<30,40,IF(R6<=40,60+(R6-30)*3,60+30+(R6-40)*4)))) -> 0 | AM6: =SUM(X6:AL6) -> 0
A7: AQ10815 | B7: EL REGAD HIND | C7: MARAVILLA | S7: =SUM(D7:R7) -> 0 | T7: 1 | U7: AQ10815 | V7: EL REGAD HIND | W7: MARAVILLA | X7: =IF(D7<20,0,IF(D7<25,20,IF(D7<30,40,IF(D7<=40,60+(D7-30)*3,60+30+(D7-40)*4)))) -> 0 | Y7: =IF(E7<20,0,IF(E7<25,20,IF(E7<30,40,IF(E7<=40,60+(E7-30)*3,60+30+(E7-40)*4)))) -> 0 | Z7: =IF(F7<20,0,IF(F7<25,20,IF(F7<30,40,IF(F7<=40,60+(F7-30)*3,60+30+(F7-40)*4)))) -> 0 | AA7: =IF(G7<20,0,IF(G7<25,20,IF(G7<30,40,IF(G7<=40,60+(G7-30)*3,60+30+(G7-40)*4)))) -> 0 | AB7: =IF(H7<20,0,IF(H7<25,20,IF(H7<30,40,IF(H7<=40,60+(H7-30)*3,60+30+(H7-40)*4)))) -> 0 | AC7: =IF(I7<20,0,IF(I7<25,20,IF(I7<30,40,IF(I7<=40,60+(I7-30)*3,60+30+(I7-40)*4)))) -> 0 | AD7: =IF(J7<20,0,IF(J7<25,20,IF(J7<30,40,IF(J7<=40,60+(J7-30)*3,60+30+(J7-40)*4)))) -> 0 | AE7: =IF(K7<20,0,IF(K7<25,20,IF(K7<30,40,IF(K7<=40,60+(K7-30)*3,60+30+(K7-40)*4)))) -> 0 | ... AL7: =IF(R7<20,0,IF(R7<25,20,IF(R7<30,40,IF(R7<=40,60+(R7-30)*3,60+30+(R7-40)*4)))) -> 0 | AM7: =SUM(X7:AL7) -> 0
A8: AQ10816 | B8: AL ABDI BOUCHRA | C8: MARAVILLA | S8: =SUM(D8:R8) -> 0 | T8: 1 | U8: AQ10816 | V8: AL ABDI BOUCHRA | W8: MARAVILLA | X8: =IF(D8<20,0,IF(D8<25,20,IF(D8<30,40,IF(D8<=40,60+(D8-30)*3,60+30+(D8-40)*4)))) -> 0 | Y8: =IF(E8<20,0,IF(E8<25,20,IF(E8<30,40,IF(E8<=40,60+(E8-30)*3,60+30+(E8-40)*4)))) -> 0 | Z8: =IF(F8<20,0,IF(F8<25,20,IF(F8<30,40,IF(F8<=40,60+(F8-30)*3,60+30+(F8-40)*4)))) -> 0 | AA8: =IF(G8<20,0,IF(G8<25,20,IF(G8<30,40,IF(G8<=40,60+(G8-30)*3,60+30+(G8-40)*4)))) -> 0 | AB8: =IF(H8<20,0,IF(H8<25,20,IF(H8<30,40,IF(H8<=40,60+(H8-30)*3,60+30+(H8-40)*4)))) -> 0 | AC8: =IF(I8<20,0,IF(I8<25,20,IF(I8<30,40,IF(I8<=40,60+(I8-30)*3,60+30+(I8-40)*4)))) -> 0 | AD8: =IF(J8<20,0,IF(J8<25,20,IF(J8<30,40,IF(J8<=40,60+(J8-30)*3,60+30+(J8-40)*4)))) -> 0 | AE8: =IF(K8<20,0,IF(K8<25,20,IF(K8<30,40,IF(K8<=40,60+(K8-30)*3,60+30+(K8-40)*4)))) -> 0 | ... AL8: =IF(R8<20,0,IF(R8<25,20,IF(R8<30,40,IF(R8<=40,60+(R8-30)*3,60+30+(R8-40)*4)))) -> 0 | AM8: =SUM(X8:AL8) -> 0
A9: CA10539 | B9: BENAYAD ASSIA | C9: MARAVILLA | S9: =SUM(D9:R9) -> 0 | T9: 1 | U9: CA10539 | V9: BENAYAD ASSIA | W9: MARAVILLA | X9: =IF(D9<20,0,IF(D9<25,20,IF(D9<30,40,IF(D9<=40,60+(D9-30)*3,60+30+(D9-40)*4)))) -> 0 | Y9: =IF(E9<20,0,IF(E9<25,20,IF(E9<30,40,IF(E9<=40,60+(E9-30)*3,60+30+(E9-40)*4)))) -> 0 | Z9: =IF(F9<20,0,IF(F9<25,20,IF(F9<30,40,IF(F9<=40,60+(F9-30)*3,60+30+(F9-40)*4)))) -> 0 | AA9: =IF(G9<20,0,IF(G9<25,20,IF(G9<30,40,IF(G9<=40,60+(G9-30)*3,60+30+(G9-40)*4)))) -> 0 | AB9: =IF(H9<20,0,IF(H9<25,20,IF(H9<30,40,IF(H9<=40,60+(H9-30)*3,60+30+(H9-40)*4)))) -> 0 | AC9: =IF(I9<20,0,IF(I9<25,20,IF(I9<30,40,IF(I9<=40,60+(I9-30)*3,60+30+(I9-40)*4)))) -> 0 | AD9: =IF(J9<20,0,IF(J9<25,20,IF(J9<30,40,IF(J9<=40,60+(J9-30)*3,60+30+(J9-40)*4)))) -> 0 | AE9: =IF(K9<20,0,IF(K9<25,20,IF(K9<30,40,IF(K9<=40,60+(K9-30)*3,60+30+(K9-40)*4)))) -> 0 | ... AL9: =IF(R9<20,0,IF(R9<25,20,IF(R9<30,40,IF(R9<=40,60+(R9-30)*3,60+30+(R9-40)*4)))) -> 0 | AM9: =SUM(X9:AL9) -> 0
A10: CA10565 | B10: EL HAMAMI ZAKIA | C10: MARAVILLA | D10: 9 | E10: 9 | F10: 9 | G10: 10.5 | H10: 7.5 | J10: 39 | K10: 40.5 | L10: 57 | M10: 63 | S10: =SUM(D10:R10) -> 244.5 | T10: 1 | U10: CA10565 | V10: EL HAMAMI ZAKIA | W10: MARAVILLA | X10: =IF(D10<20,0,IF(D10<25,20,IF(D10<30,40,IF(D10<=40,60+(D10-30)*3,60+30+(D10-40)*4)))) -> 0 | Y10: =IF(E10<20,0,IF(E10<25,20,IF(E10<30,40,IF(E10<=40,60+(E10-30)*3,60+30+(E10-40)*4)))) -> 0 | Z10: =IF(F10<20,0,IF(F10<25,20,IF(F10<30,40,IF(F10<=40,60+(F10-30)*3,60+30+(F10-40)*4)))) -> 0 | AA10: =IF(G10<20,0,IF(G10<25,20,IF(G10<30,40,IF(G10<=40,60+(G10-30)*3,60+30+(G10-40)*4)))) -> 0 | AB10: =IF(H10<20,0,IF(H10<25,20,IF(H10<30,40,IF(H10<=40,60+(H10-30)*3,60+30+(H10-40)*4)))) -> 0 | AC10: =IF(I10<20,0,IF(I10<25,20,IF(I10<30,40,IF(I10<=40,60+(I10-30)*3,60+30+(I10-40)*4)))) -> 0 | AD10: =IF(J10<20,0,IF(J10<25,20,IF(J10<30,40,IF(J10<=40,60+(J10-30)*3,60+30+(J10-40)*4)))) -> 87 | AE10: =IF(K10<20,0,IF(K10<25,20,IF(K10<30,40,IF(K10<=40,60+(K10-30)*3,60+30+(K10-40)*4)))) -> 92 | ... AL10: =IF(R10<20,0,IF(R10<25,20,IF(R10<30,40,IF(R10<=40,60+(R10-30)*3,60+30+(R10-40)*4)))) -> 0 | AM10: =SUM(X10:AL10) -> 519
A11: CA10566 | B11: REGRAGUI GHITA | C11: MARAVILLA | D11: 9 | E11: 7.5 | F11: 9 | G11: 12 | I11: 22.5 | J11: 25.5 | K11: 39 | L11: 49.5 | M11: 51 | S11: =SUM(D11:R11) -> 225 | T11: 1 | U11: CA10566 | V11: REGRAGUI GHITA | W11: MARAVILLA | X11: =IF(D11<20,0,IF(D11<25,20,IF(D11<30,40,IF(D11<=40,60+(D11-30)*3,60+30+(D11-40)*4)))) -> 0 | Y11: =IF(E11<20,0,IF(E11<25,20,IF(E11<30,40,IF(E11<=40,60+(E11-30)*3,60+30+(E11-40)*4)))) -> 0 | Z11: =IF(F11<20,0,IF(F11<25,20,IF(F11<30,40,IF(F11<=40,60+(F11-30)*3,60+30+(F11-40)*4)))) -> 0 | AA11: =IF(G11<20,0,IF(G11<25,20,IF(G11<30,40,IF(G11<=40,60+(G11-30)*3,60+30+(G11-40)*4)))) -> 0 | AB11: =IF(H11<20,0,IF(H11<25,20,IF(H11<30,40,IF(H11<=40,60+(H11-30)*3,60+30+(H11-40)*4)))) -> 0 | AC11: =IF(I11<20,0,IF(I11<25,20,IF(I11<30,40,IF(I11<=40,60+(I11-30)*3,60+30+(I11-40)*4)))) -> 20 | AD11: =IF(J11<20,0,IF(J11<25,20,IF(J11<30,40,IF(J11<=40,60+(J11-30)*3,60+30+(J11-40)*4)))) -> 40 | AE11: =IF(K11<20,0,IF(K11<25,20,IF(K11<30,40,IF(K11<=40,60+(K11-30)*3,60+30+(K11-40)*4)))) -> 87 | ... AL11: =IF(R11<20,0,IF(R11<25,20,IF(R11<30,40,IF(R11<=40,60+(R11-30)*3,60+30+(R11-40)*4)))) -> 0 | AM11: =SUM(X11:AL11) -> 409
A12: CA10567 | B12: FERJANI ZOUHRA | C12: MARAVILLA | E12: 6 | F12: 6 | G12: 9 | H12: 4.5 | M12: 33 | S12: =SUM(D12:R12) -> 58.5 | T12: 1 | U12: CA10567 | V12: FERJANI ZOUHRA | W12: MARAVILLA | X12: =IF(D12<20,0,IF(D12<25,20,IF(D12<30,40,IF(D12<=40,60+(D12-30)*3,60+30+(D12-40)*4)))) -> 0 | Y12: =IF(E12<20,0,IF(E12<25,20,IF(E12<30,40,IF(E12<=40,60+(E12-30)*3,60+30+(E12-40)*4)))) -> 0 | Z12: =IF(F12<20,0,IF(F12<25,20,IF(F12<30,40,IF(F12<=40,60+(F12-30)*3,60+30+(F12-40)*4)))) -> 0 | AA12: =IF(G12<20,0,IF(G12<25,20,IF(G12<30,40,IF(G12<=40,60+(G12-30)*3,60+30+(G12-40)*4)))) -> 0 | AB12: =IF(H12<20,0,IF(H12<25,20,IF(H12<30,40,IF(H12<=40,60+(H12-30)*3,60+30+(H12-40)*4)))) -> 0 | AC12: =IF(I12<20,0,IF(I12<25,20,IF(I12<30,40,IF(I12<=40,60+(I12-30)*3,60+30+(I12-40)*4)))) -> 0 | AD12: =IF(J12<20,0,IF(J12<25,20,IF(J12<30,40,IF(J12<=40,60+(J12-30)*3,60+30+(J12-40)*4)))) -> 0 | AE12: =IF(K12<20,0,IF(K12<25,20,IF(K12<30,40,IF(K12<=40,60+(K12-30)*3,60+30+(K12-40)*4)))) -> 0 | ... AL12: =IF(R12<20,0,IF(R12<25,20,IF(R12<30,40,IF(R12<=40,60+(R12-30)*3,60+30+(R12-40)*4)))) -> 0 | AM12: =SUM(X12:AL12) -> 69
A13: CA10569 | B13: EL BOUAINI ABDENBI | C13: MARAVILLA | K13: 19.5 | L13: 48 | M13: 40.5 | S13: =SUM(D13:R13) -> 108 | T13: 1 | U13: CA10569 | V13: EL BOUAINI ABDENBI | W13: MARAVILLA | X13: =IF(D13<20,0,IF(D13<25,20,IF(D13<30,40,IF(D13<=40,60+(D13-30)*3,60+30+(D13-40)*4)))) -> 0 | Y13: =IF(E13<20,0,IF(E13<25,20,IF(E13<30,40,IF(E13<=40,60+(E13-30)*3,60+30+(E13-40)*4)))) -> 0 | Z13: =IF(F13<20,0,IF(F13<25,20,IF(F13<30,40,IF(F13<=40,60+(F13-30)*3,60+30+(F13-40)*4)))) -> 0 | AA13: =IF(G13<20,0,IF(G13<25,20,IF(G13<30,40,IF(G13<=40,60+(G13-30)*3,60+30+(G13-40)*4)))) -> 0 | AB13: =IF(H13<20,0,IF(H13<25,20,IF(H13<30,40,IF(H13<=40,60+(H13-30)*3,60+30+(H13-40)*4)))) -> 0 | AC13: =IF(I13<20,0,IF(I13<25,20,IF(I13<30,40,IF(I13<=40,60+(I13-30)*3,60+30+(I13-40)*4)))) -> 0 | AD13: =IF(J13<20,0,IF(J13<25,20,IF(J13<30,40,IF(J13<=40,60+(J13-30)*3,60+30+(J13-40)*4)))) -> 0 | AE13: =IF(K13<20,0,IF(K13<25,20,IF(K13<30,40,IF(K13<=40,60+(K13-30)*3,60+30+(K13-40)*4)))) -> 0 | ... AL13: =IF(R13<20,0,IF(R13<25,20,IF(R13<30,40,IF(R13<=40,60+(R13-30)*3,60+30+(R13-40)*4)))) -> 0 | AM13: =SUM(X13:AL13) -> 214
A14: CA10657 | B14: EL HAMAMI MOHAMED | C14: MARAVILLA | K14: 19.5 | L14: 27 | S14: =SUM(D14:R14) -> 46.5 | T14: 1 | U14: CA10657 | V14: EL HAMAMI MOHAMED | W14: MARAVILLA | X14: =IF(D14<20,0,IF(D14<25,20,IF(D14<30,40,IF(D14<=40,60+(D14-30)*3,60+30+(D14-40)*4)))) -> 0 | Y14: =IF(E14<20,0,IF(E14<25,20,IF(E14<30,40,IF(E14<=40,60+(E14-30)*3,60+30+(E14-40)*4)))) -> 0 | Z14: =IF(F14<20,0,IF(F14<25,20,IF(F14<30,40,IF(F14<=40,60+(F14-30)*3,60+30+(F14-40)*4)))) -> 0 | AA14: =IF(G14<20,0,IF(G14<25,20,IF(G14<30,40,IF(G14<=40,60+(G14-30)*3,60+30+(G14-40)*4)))) -> 0 | AB14: =IF(H14<20,0,IF(H14<25,20,IF(H14<30,40,IF(H14<=40,60+(H14-30)*3,60+30+(H14-40)*4)))) -> 0 | AC14: =IF(I14<20,0,IF(I14<25,20,IF(I14<30,40,IF(I14<=40,60+(I14-30)*3,60+30+(I14-40)*4)))) -> 0 | AD14: =IF(J14<20,0,IF(J14<25,20,IF(J14<30,40,IF(J14<=40,60+(J14-30)*3,60+30+(J14-40)*4)))) -> 0 | AE14: =IF(K14<20,0,IF(K14<25,20,IF(K14<30,40,IF(K14<=40,60+(K14-30)*3,60+30+(K14-40)*4)))) -> 0 | ... AL14: =IF(R14<20,0,IF(R14<25,20,IF(R14<30,40,IF(R14<=40,60+(R14-30)*3,60+30+(R14-40)*4)))) -> 0 | AM14: =SUM(X14:AL14) -> 40
A15: CA10700 | B15: HAFOUDA ILIYASS | C15: MARAVILLA | S15: =SUM(D15:R15) -> 0 | T15: 1 | U15: CA10700 | V15: HAFOUDA ILIYASS | W15: MARAVILLA | X15: =IF(D15<20,0,IF(D15<25,20,IF(D15<30,40,IF(D15<=40,60+(D15-30)*3,60+30+(D15-40)*4)))) -> 0 | Y15: =IF(E15<20,0,IF(E15<25,20,IF(E15<30,40,IF(E15<=40,60+(E15-30)*3,60+30+(E15-40)*4)))) -> 0 | Z15: =IF(F15<20,0,IF(F15<25,20,IF(F15<30,40,IF(F15<=40,60+(F15-30)*3,60+30+(F15-40)*4)))) -> 0 | AA15: =IF(G15<20,0,IF(G15<25,20,IF(G15<30,40,IF(G15<=40,60+(G15-30)*3,60+30+(G15-40)*4)))) -> 0 | AB15: =IF(H15<20,0,IF(H15<25,20,IF(H15<30,40,IF(H15<=40,60+(H15-30)*3,60+30+(H15-40)*4)))) -> 0 | AC15: =IF(I15<20,0,IF(I15<25,20,IF(I15<30,40,IF(I15<=40,60+(I15-30)*3,60+30+(I15-40)*4)))) -> 0 | AD15: =IF(J15<20,0,IF(J15<25,20,IF(J15<30,40,IF(J15<=40,60+(J15-30)*3,60+30+(J15-40)*4)))) -> 0 | AE15: =IF(K15<20,0,IF(K15<25,20,IF(K15<30,40,IF(K15<=40,60+(K15-30)*3,60+30+(K15-40)*4)))) -> 0 | ... AL15: =IF(R15<20,0,IF(R15<25,20,IF(R15<30,40,IF(R15<=40,60+(R15-30)*3,60+30+(R15-40)*4)))) -> 0 | AM15: =SUM(X15:AL15) -> 0
A16: CA10755 | B16: ASSILA KARIM | C16: MARAVILLA | K16: 15 | L16: 48 | M16: 36 | S16: =SUM(D16:R16) -> 99 | T16: 1 | U16: CA10755 | V16: ASSILA KARIM | W16: MARAVILLA | X16: =IF(D16<20,0,IF(D16<25,20,IF(D16<30,40,IF(D16<=40,60+(D16-30)*3,60+30+(D16-40)*4)))) -> 0 | Y16: =IF(E16<20,0,IF(E16<25,20,IF(E16<30,40,IF(E16<=40,60+(E16-30)*3,60+30+(E16-40)*4)))) -> 0 | Z16: =IF(F16<20,0,IF(F16<25,20,IF(F16<30,40,IF(F16<=40,60+(F16-30)*3,60+30+(F16-40)*4)))) -> 0 | AA16: =IF(G16<20,0,IF(G16<25,20,IF(G16<30,40,IF(G16<=40,60+(G16-30)*3,60+30+(G16-40)*4)))) -> 0 | AB16: =IF(H16<20,0,IF(H16<25,20,IF(H16<30,40,IF(H16<=40,60+(H16-30)*3,60+30+(H16-40)*4)))) -> 0 | AC16: =IF(I16<20,0,IF(I16<25,20,IF(I16<30,40,IF(I16<=40,60+(I16-30)*3,60+30+(I16-40)*4)))) -> 0 | AD16: =IF(J16<20,0,IF(J16<25,20,IF(J16<30,40,IF(J16<=40,60+(J16-30)*3,60+30+(J16-40)*4)))) -> 0 | AE16: =IF(K16<20,0,IF(K16<25,20,IF(K16<30,40,IF(K16<=40,60+(K16-30)*3,60+30+(K16-40)*4)))) -> 0 | ... AL16: =IF(R16<20,0,IF(R16<25,20,IF(R16<30,40,IF(R16<=40,60+(R16-30)*3,60+30+(R16-40)*4)))) -> 0 | AM16: =SUM(X16:AL16) -> 200
A17: CA10766 | B17: ZAOUY MOHAMED | C17: MARAVILLA | S17: =SUM(D17:R17) -> 0 | T17: 1 | U17: CA10766 | V17: ZAOUY MOHAMED | W17: MARAVILLA | X17: =IF(D17<20,0,IF(D17<25,20,IF(D17<30,40,IF(D17<=40,60+(D17-30)*3,60+30+(D17-40)*4)))) -> 0 | Y17: =IF(E17<20,0,IF(E17<25,20,IF(E17<30,40,IF(E17<=40,60+(E17-30)*3,60+30+(E17-40)*4)))) -> 0 | Z17: =IF(F17<20,0,IF(F17<25,20,IF(F17<30,40,IF(F17<=40,60+(F17-30)*3,60+30+(F17-40)*4)))) -> 0 | AA17: =IF(G17<20,0,IF(G17<25,20,IF(G17<30,40,IF(G17<=40,60+(G17-30)*3,60+30+(G17-40)*4)))) -> 0 | AB17: =IF(H17<20,0,IF(H17<25,20,IF(H17<30,40,IF(H17<=40,60+(H17-30)*3,60+30+(H17-40)*4)))) -> 0 | AC17: =IF(I17<20,0,IF(I17<25,20,IF(I17<30,40,IF(I17<=40,60+(I17-30)*3,60+30+(I17-40)*4)))) -> 0 | AD17: =IF(J17<20,0,IF(J17<25,20,IF(J17<30,40,IF(J17<=40,60+(J17-30)*3,60+30+(J17-40)*4)))) -> 0 | AE17: =IF(K17<20,0,IF(K17<25,20,IF(K17<30,40,IF(K17<=40,60+(K17-30)*3,60+30+(K17-40)*4)))) -> 0 | ... AL17: =IF(R17<20,0,IF(R17<25,20,IF(R17<30,40,IF(R17<=40,60+(R17-30)*3,60+30+(R17-40)*4)))) -> 0 | AM17: =SUM(X17:AL17) -> 0
A18: CA10850 | B18: CHAFIK SOUAD | C18: MARAVILLA | F18: 7.5 | G18: 6 | H18: 6 | I18: 13.5 | J18: 16.5 | K18: 30 | M18: 36 | S18: =SUM(D18:R18) -> 115.5 | T18: 1 | U18: CA10850 | V18: CHAFIK SOUAD | W18: MARAVILLA | X18: =IF(D18<20,0,IF(D18<25,20,IF(D18<30,40,IF(D18<=40,60+(D18-30)*3,60+30+(D18-40)*4)))) -> 0 | Y18: =IF(E18<20,0,IF(E18<25,20,IF(E18<30,40,IF(E18<=40,60+(E18-30)*3,60+30+(E18-40)*4)))) -> 0 | Z18: =IF(F18<20,0,IF(F18<25,20,IF(F18<30,40,IF(F18<=40,60+(F18-30)*3,60+30+(F18-40)*4)))) -> 0 | AA18: =IF(G18<20,0,IF(G18<25,20,IF(G18<30,40,IF(G18<=40,60+(G18-30)*3,60+30+(G18-40)*4)))) -> 0 | AB18: =IF(H18<20,0,IF(H18<25,20,IF(H18<30,40,IF(H18<=40,60+(H18-30)*3,60+30+(H18-40)*4)))) -> 0 | AC18: =IF(I18<20,0,IF(I18<25,20,IF(I18<30,40,IF(I18<=40,60+(I18-30)*3,60+30+(I18-40)*4)))) -> 0 | AD18: =IF(J18<20,0,IF(J18<25,20,IF(J18<30,40,IF(J18<=40,60+(J18-30)*3,60+30+(J18-40)*4)))) -> 0 | AE18: =IF(K18<20,0,IF(K18<25,20,IF(K18<30,40,IF(K18<=40,60+(K18-30)*3,60+30+(K18-40)*4)))) -> 60 | ... AL18: =IF(R18<20,0,IF(R18<25,20,IF(R18<30,40,IF(R18<=40,60+(R18-30)*3,60+30+(R18-40)*4)))) -> 0 | AM18: =SUM(X18:AL18) -> 138
